Workbook

Sheet 0_origin
A1: _id | B1: units | C1: specifier | D1: doi | E1: solvent | F1: standard_value | G1: smiles | H1: corrected | I1: context | O1: solutionkeywords
A2: 0 | B2: (10^-9.0) * Meter^(1.0) | C2: λema | D2: https://doi.org/10.1016/j.cej.2022.135775 | F2: 638 | G2: N1=CC=C(C=C1)C=1C=C2N=C3C(=NC2=CC1C1=CC=NC=C1)C=1C=CC(=C2C=CC=C3C12)N1C2=CC=CC=C2OC=2C=CC=CC12 | H2: 0 | I2: 638 🙃🙃🙃🙃 pDPAPQ - PXZ 🙃🙃🙃🙃 λema [ nm ]; Summary of the photophysical properties of pDPAPQ-PXZ and pDPBPZ-PXZ. | O2: toluene
A3: 1 | B3: (10^-9.0) * Meter^(1.0) | C3: λema | D3: https://doi.org/10.1016/j.cej.2022.135775 | F3: 639 | G3: N1=CC=C(C=C1)C=1C=C2N=C3C4=C(C5=C(C3=NC2=CC1C1=CC=NC=C1)C=CC(=C5)N5C1=CC=CC=C1OC=1C=CC=CC51)C=CC=C4 | H3: 0 | I3: 639 🙃🙃🙃🙃 pDPBPZ - PXZ 🙃🙃🙃🙃 λema [ nm ]; Summary of the photophysical properties of pDPAPQ-PXZ and pDPBPZ-PXZ. | O3: thf
A4: 2 | B4: (10^-9.0) * Meter^(1.0) | C4: λem | D4: https://doi.org/10.1016/j.dyepig.2023.111250 | F4: 402 | G4: C1(=CC=CC=C1)C1=NC(=NC(=N1)C1=CC=CC=C1)C1=C(C=CC=C1)N1C2=CC=CC=C2C=2C=CC=CC12 | H4: 0 | I4: 402 🙃🙃🙃🙃 oCzTrz 🙃🙃🙃🙃 λem ( nm ) ; Wavelength of the singlet emission at the onset position .; Summary of the electrochemical and photophysical properties of oCzTrz and PhoCzTrz. | O4: dcm
A5: 4 | B5: (10^-9.0) * Meter^(1.0) | C5: λPL | D5: https://doi.org/10.1016/j.jphotochem.2024.116046 | E5: toluene | F5: 440 | G5: C(C)(C)(C)C=1C=CC=2N(C3=CC=C(C=C3C2C1)C(C)(C)C)CCCCCCCCC1(C2=CC=CC=C2C=2C=CC(=CC12)C1=C2C=CC=CC2=C(C2=CC=CC=C12)C1=CC=C(C#N)C=C1)CCCCCCCCN1C2=CC=C(C=C2C=2C=C(C=CC12)C(C)(C)C)C(C)(C)C | H5: 0 | I5: 440 / 449 🙃🙃🙃🙃 FAnCN 🙃🙃🙃🙃 λPL ( nm ) sola / filmb; The physical and photophysical data of the emitters. | O5: dichloro
A6: 5 | B6: (10^-9.0) * Meter^(1.0) | C6: λPL | D6: https://doi.org/10.1016/j.jphotochem.2024.116046 | E6: toluene | F6: 424 | G6: C(C)(C)(C)C=1C=CC=2N(C3=CC=C(C=C3C2C1)C(C)(C)C)CCCCCCCCC1(C2=CC=CC=C2C=2C=CC(=CC12)C1=CC2=C3C=CC=CC3=C(C=C2C=2C=CC=CC12)C1=CC=C(C#N)C=C1)CCCCCCCCN1C2=CC=C(C=C2C=2C=C(C=CC12)C(C)(C)C)C(C)(C)C | H6: 0 | I6: 424 / 439 🙃🙃🙃🙃 FCsCN 🙃🙃🙃🙃 λPL ( nm ) sola / filmb; The physical and photophysical data of the emitters. | O6: ch2cl2
A7: 6 | B7: (10^-9.0) * Meter^(1.0) | C7: λem | D7: https://doi.org/10.1016/j.dyepig.2021.109649 | F7: 536 | G7: CC1(C2=CC=CC=C2N(C=2C=CC=CC12)C1=CC=C(C=C1)C(=O)C1=CC=C(C=C1)SC1=CC=CC=C1)C | H7: 0 | I7: 536 🙃🙃🙃🙃 PT - BZ - DMAC 🙃🙃🙃🙃 λem [ nm ] ; Absorption and PL peak wavelengths in dilute toluene solutions at RT .; Summary of physical parameters of PT-BZ-DMAC and PS-BZ-DMAC. | O7: chloroform
A8: 7 | B8: (10^-9.0) * Meter^(1.0) | C8: λem | D8: https://doi.org/10.1016/j.dyepig.2021.109649 | F8: 574 | G8: CC1(C2=CC=CC=C2N(C=2C=CC=CC12)C1=CC=C(C=C1)C(=O)C1=CC=C(C=C1)S(=O)(=O)C1=CC=CC=C1)C | H8: 0 | I8: 574 🙃🙃🙃🙃 PS - BZ - DMAC 🙃🙃🙃🙃 λem [ nm ] ; Absorption and PL peak wavelengths in dilute toluene solutions at RT .; Summary of physical parameters of PT-BZ-DMAC and PS-BZ-DMAC. | O8: cdcl3
A9: 8 | B9: (10^-9.0) * Meter^(1.0) | C9: λPL | D9: https://doi.org/10.1016/j.jlumin.2021.118683 | E9: toluene | F9: 654 | G9: C(C)(C)C1=C(C(=CC=C1)C(C)C)N1C(C2=CC(=CC=3C2=C(C1=O)C=C(C3)N3C=1C=CC=CC1C(C1=CC=CC=C31)(C)C)N3C=1C=CC=CC1C(C1=CC=CC=C31)(C)C)=O | H9: 0 | I9: 654 / 646 / 618 Measured in toluene solutions ( 1 × 10−5 M ) . Measured in neat film . Measured in doped mCPCN film . 🙃🙃🙃🙃 2DN 🙃🙃🙃🙃 λPL [ nm ]; Summaries of physical data of 2DN and 2PN. | O9: solution
A10: 9 | B10: (10^-9.0) * Meter^(1.0) | C10: λPL | D10: https://doi.org/10.1016/j.jlumin.2021.118683 | E10: toluene | F10: 755 | G10: C(C)(C)C1=C(C(=CC=C1)C(C)C)N1C(C2=CC(=CC=3C2=C(C1=O)C=C(C3)N3C1=CC=CC=C1OC=1C=CC=CC31)N3C1=CC=CC=C1OC=1C=CC=CC31)=O | H10: 0 | I10: 755 / 725 / 650 Measured in toluene solutions ( 1 × 10−5 M ) . Measured in neat film . Measured in doped mCPCN film . 🙃🙃🙃🙃 2PN 🙃🙃🙃🙃 λPL [ nm ]; Summaries of physical data of 2DN and 2PN. | O10: solvent
A11: 11 | B11: (10^-9.0) * Meter^(1.0) | C11: PL | D11: https://doi.org/10.1016/j.dyepig.2024.112417 | E11: toluene | F11: 440 | G11: C(C)(C)(C)C1=CC=C(C=C1)N(C1=CC=C(C=C1)C=1N(C(=C(N1)C#N)C#N)C)C1=CC=C(C=C1)C(C)(C)C | H11: 0 | I11: 440 / 463 🙃🙃🙃🙃 DCI - TPA 🙃🙃🙃🙃 PL / PL ( nm ) ; Measured in toluene solution . ; Measured in neat films .; Photophysical, electrochemical and thermal properties of the compounds. | O11: dissolve
A12: 13 | B12: (10^-9.0) * Meter^(1.0) | C12: PL | D12: https://doi.org/10.1016/j.dyepig.2024.112417 | E12: toluene | F12: 457 | G12: C(C)(C)(C)C1=CC=C(C=C1)N(C1=CC=C(C=C1)C1=NC2=C(N1C)C=C(C(=C2)C#N)C#N)C2=CC=C(C=C2)C(C)(C)C | H12: 0 | I12: 457 / 460 🙃🙃🙃🙃 DCBI - TPA 🙃🙃🙃🙃 PL / PL ( nm ) ; Measured in toluene solution . ; Measured in neat films .; Photophysical, electrochemical and thermal properties of the compounds. | O12: hexane
A13: 14 | B13: (10^-9.0) * Meter^(1.0) | C13: λem | D13: https://doi.org/10.1016/j.cej.2020.126173 | E13: toluene | F13: 479 | G13: C1(=CC=CC=C1)C1=NC(=NC(=N1)C1=CC=CC=C1)C1=C(C=CC=C1)N1C=2C=CC=CC2C=2C=CC3=C(C12)C1=CC=CC=C1C31C3=CC=CC=C3C=3C=CC=CC31 | H13: 0 | I13: 479 🙃🙃🙃🙃 SF34oTz 🙃🙃🙃🙃 λem ( nm ) c ; Emission peaks in toluene solution ( 1 * 10−5 M ) .; Thermal, electrochemical, and photophysical data of SFxoTzs. | O13: tetrahydr
A14: 15 | B14: (10^-9.0) * Meter^(1.0) | C14: λPL | D14: https://doi.org/10.1016/j.orgel.2018.04.045 | E14: toluene | F14: 533 | G14: C1=CC=CC=2OC3=CC=CC=C3N(C12)C=1C=CC=2C3=C(C4=CC=C(C=C4C2C1)N1C2=CC=CC=C2OC=2C=CC=CC12)N=C(C(=N3)C#N)C#N | H14: 0 | I14: 533 / 564 🙃🙃🙃🙃 PXZ - DCPP 🙃🙃🙃🙃 λPL ( nm ) soln / doped film ; Measured in dilute toluene solution and doped CBP film on quartz , respectively .; The thermal, electrochemical and photophysical properties of PXZ-DCPP and PTZ-DCPP. | O14: chcl3
A15: 16 | B15: (10^-9.0) * Meter^(1.0) | C15: λPL | D15: https://doi.org/10.1016/j.orgel.2018.04.045 | E15: toluene | F15: 539 | G15: C1=CC=CC=2SC3=CC=CC=C3N(C12)C=1C=CC=2C3=C(C4=CC=C(C=C4C2C1)N1C2=CC=CC=C2SC=2C=CC=CC12)N=C(C(=N3)C#N)C#N | H15: 0 | I15: 539 / 580 🙃🙃🙃🙃 PTZ - DCPP 🙃🙃🙃🙃 λPL ( nm ) soln / doped film ; Measured in dilute toluene solution and doped CBP film on quartz , respectively .; The thermal, electrochemical and photophysical properties of PXZ-DCPP and PTZ-DCPP. | O15: dilute
A16: 17 | B16: (10^-9.0) * Meter^(1.0) | C16: λPLc | D16: https://doi.org/10.1016/j.cej.2020.127591 | F16: 415 | G16: C1=CC=CC=2C=3C=CC4=C(C3N(C12)C1=NC=C(N=C1)N1C=2C=CC=CC2C=2C=CC3=C(C12)OC1=C3C=CC=C1)OC1=C4C=CC=C1 | H16: 0 | I16: 415 🙃🙃🙃🙃 BFCZPZ1 🙃🙃🙃🙃 λPLc [ nm ]; Physical properties of six materials.
A17: 18 | B17: (10^-9.0) * Meter^(1.0) | C17: λPLc | D17: https://doi.org/10.1016/j.cej.2020.127591 | F17: 444 | G17: C1=C2C=3C4=C(C=CC3N(C2=CC=C1)C1=NC=C(N=C1)N1C2=CC=CC=C2C=2C3=C(C=CC12)C1=C(O3)C=CC=C1)C1=C(O4)C=CC=C1 | H17: 0 | I17: 444 🙃🙃🙃🙃 BFCZPZ2 🙃🙃🙃🙃 λPLc [ nm ]; Physical properties of six materials.
A18: 19 | B18: (10^-9.0) * Meter^(1.0) | C18: λPLc | D18: https://doi.org/10.1016/j.cej.2020.127591 | F18: 444 | G18: C1=CC=CC2=C1C=1C(=CC=C3C4=CC=CC=C4N(C13)C1=NC=C(N=C1)N1C3=CC=CC=C3C3=CC=C4C(=C13)C1=C(O4)C=CC=C1)O2 | H18: 0 | I18: 444 🙃🙃🙃🙃 BFCZPZ3 🙃🙃🙃🙃 λPLc [ nm ]; Physical properties of six materials.
A19: 20 | B19: (10^-9.0) * Meter^(1.0) | C19: λPLc | D19: https://doi.org/10.1016/j.cej.2020.127591 | F19: 456 | G19: C1=CC=CC=2C=3C=CC4=C(C3N(C12)C1=NC=C(N=C1)N1C=2C=CC=CC2C=2C=CC3=C(C12)SC1=C3C=CC=C1)SC1=C4C=CC=C1 | H19: 0 | I19: 456 🙃🙃🙃🙃 BTCZPZ1 🙃🙃🙃🙃 λPLc [ nm ]; Physical properties of six materials.
A20: 21 | B20: (10^-9.0) * Meter^(1.0) | C20: λPLc | D20: https://doi.org/10.1016/j.cej.2020.127591 | F20: 444 | G20: C1=C2C=3C4=C(C=CC3N(C2=CC=C1)C1=NC=C(N=C1)N1C2=CC=CC=C2C=2C3=C(C=CC12)C1=C(S3)C=CC=C1)C1=C(S4)C=CC=C1 | H20: 0 | I20: 444 🙃🙃🙃🙃 BTCZPZ2 🙃🙃🙃🙃 λPLc [ nm ]; Physical properties of six materials.
A21: 22 | B21: (10^-9.0) * Meter^(1.0) | C21: λPLc | D21: https://doi.org/10.1016/j.cej.2020.127591 | F21: 454 | G21: C1=CC(=CC=2C3=CC=CC=C3N(C12)C1=NC=C(N=C1)N1C2=CC=CC=C2C=2C=C(C=CC12)N1C2=CC=CC=C2C=2C=CC=CC12)N1C2=CC=CC=C2C=2C=CC=CC12 | H21: 0 | I21: 454 🙃🙃🙃🙃 CZ9CZPZ 🙃🙃🙃🙃 λPLc [ nm ]; Physical properties of six materials.
A22: 23 | B22: (10^-9.0) * Meter^(1.0) | C22: λPL | D22: https://doi.org/10.1016/j.cej.2020.127591 | F22: 430 | G22: C1=CC=CC=2C=3C=CC4=C(C3N(C12)C1=NC=C(N=C1)N1C=2C=CC=CC2C=2C=CC3=C(C12)OC1=C3C=CC=C1)OC1=C4C=CC=C1 | H22: 0 | I22: 430 🙃🙃🙃🙃 BFCZPZ1 🙃🙃🙃🙃 λPL [ nm ]; Photophysical properties of six TADF materials in 7 wt% emitter: PPT doped films.
A23: 24 | B23: (10^-9.0) * Meter^(1.0) | C23: λPL | D23: https://doi.org/10.1016/j.cej.2020.127591 | F23: 462 | G23: C1=C2C=3C4=C(C=CC3N(C2=CC=C1)C1=NC=C(N=C1)N1C2=CC=CC=C2C=2C3=C(C=CC12)C1=C(O3)C=CC=C1)C1=C(O4)C=CC=C1 | H23: 0 | I23: 462 🙃🙃🙃🙃 BFCZPZ2 🙃🙃🙃🙃 λPL [ nm ]; Photophysical properties of six TADF materials in 7 wt% emitter: PPT doped films.
A24: 25 | B24: (10^-9.0) * Meter^(1.0) | C24: λPL | D24: https://doi.org/10.1016/j.cej.2020.127591 | F24: 458 | G24: C1=CC=CC2=C1C=1C(=CC=C3C4=CC=CC=C4N(C13)C1=NC=C(N=C1)N1C3=CC=CC=C3C3=CC=C4C(=C13)C1=C(O4)C=CC=C1)O2 | H24: 0 | I24: 458 🙃🙃🙃🙃 BFCZPZ3 🙃🙃🙃🙃 λPL [ nm ]; Photophysical properties of six TADF materials in 7 wt% emitter: PPT doped films.
A25: 26 | B25: (10^-9.0) * Meter^(1.0) | C25: λPL | D25: https://doi.org/10.1016/j.cej.2020.127591 | F25: 477 | G25: C1=CC=CC=2C=3C=CC4=C(C3N(C12)C1=NC=C(N=C1)N1C=2C=CC=CC2C=2C=CC3=C(C12)SC1=C3C=CC=C1)SC1=C4C=CC=C1 | H25: 0 | I25: 477 🙃🙃🙃🙃 BTCZPZ1 🙃🙃🙃🙃 λPL [ nm ]; Photophysical properties of six TADF materials in 7 wt% emitter: PPT doped films.
A26: 27 | B26: (10^-9.0) * Meter^(1.0) | C26: λPL | D26: https://doi.org/10.1016/j.cej.2020.127591 | F26: 462 | G26: C1=C2C=3C4=C(C=CC3N(C2=CC=C1)C1=NC=C(N=C1)N1C2=CC=CC=C2C=2C3=C(C=CC12)C1=C(S3)C=CC=C1)C1=C(S4)C=CC=C1 | H26: 0 | I26: 462 🙃🙃🙃🙃 BTCZPZ2 🙃🙃🙃🙃 λPL [ nm ]; Photophysical properties of six TADF materials in 7 wt% emitter: PPT doped films.
A27: 28 | B27: (10^-9.0) * Meter^(1.0) | C27: λPL | D27: https://doi.org/10.1016/j.cej.2020.127591 | F27: 458 | G27: C1=CC(=CC=2C3=CC=CC=C3N(C12)C1=NC=C(N=C1)N1C2=CC=CC=C2C=2C=C(C=CC12)N1C2=CC=CC=C2C=2C=CC=CC12)N1C2=CC=CC=C2C=2C=CC=CC12 | H27: 0 | I27: 458 🙃🙃🙃🙃 CZ9CZPZ 🙃🙃🙃🙃 λPL [ nm ]; Photophysical properties of six TADF materials in 7 wt% emitter: PPT doped films.
A28: 29 | B28: (10^-9.0) * Meter^(1.0) | C28: λem | D28: https://doi.org/10.1016/j.dyepig.2019.107957 | E28: toluene | F28: 523 | G28: C1=CC(=CC2=C1C1=NC3=CC=C(C=C3N=C1C1=C2C=C(C=C1)C1=CC=C(N(C2=CC=CC=C2)C2=CC=CC=C2)C=C1)C1=CC=C(N(C2=CC=CC=C2)C2=CC=CC=C2)C=C1)C1=CC=C(N(C2=CC=CC=C2)C2=CC=CC=C2)C=C1 | H28: 0 | I28: 523 , 544 , 527 Measured in toluene at 300 K . Measured in thin films on quartz substrate at 300 K . Measured in doped films on quartz substrate at 300 K . 🙃🙃🙃🙃 DBP -3TPA 🙃🙃🙃🙃 λem [ nm ]; Thermal, photophysical, and electrochemical properties of these compounds.
A29: 30 | B29: (10^-9.0) * Meter^(1.0) | C29: λem | D29: https://doi.org/10.1016/j.dyepig.2019.107957 | E29: toluene | F29: 533 | G29: C1=CC(=CC2=C1C1=NC3=CC(=C(C=C3N=C1C1=C2C=C(C=C1)C1=CC=C(N(C2=CC=CC=C2)C2=CC=CC=C2)C=C1)C1=CC=C(N(C2=CC=CC=C2)C2=CC=CC=C2)C=C1)C1=CC=C(N(C2=CC=CC=C2)C2=CC=CC=C2)C=C1)C1=CC=C(N(C2=CC=CC=C2)C2=CC=CC=C2)C=C1 | H29: 0 | I29: 533 , 552 , 532 Measured in toluene at 300 K . Measured in thin films on quartz substrate at 300 K . Measured in doped films on quartz substrate at 300 K . 🙃🙃🙃🙃 DBP -4TPA 🙃🙃🙃🙃 λem [ nm ]; Thermal, photophysical, and electrochemical properties of these compounds.
A30: 31 | B30: (10^-9.0) * Meter^(1.0) | C30: λem | D30: https://doi.org/10.1016/j.dyepig.2019.107957 | E30: toluene | F30: 569 | G30: C1=CC(=CC2=C1C1=NC3=CC=C(C=C3N=C1C1=C2C=C(C=C1)C1=CC=C(N(C2=CC=C(C=C2)OC)C2=CC=C(C=C2)OC)C=C1)C1=CC=C(N(C2=CC=C(C=C2)OC)C2=CC=C(C=C2)OC)C=C1)C1=CC=C(N(C2=CC=C(C=C2)OC)C2=CC=C(C=C2)OC)C=C1 | H30: 0 | I30: 569 , 614 , 579 Measured in toluene at 300 K . Measured in thin films on quartz substrate at 300 K . Measured in doped films on quartz substrate at 300 K . 🙃🙃🙃🙃 DBP -3MOTPA 🙃🙃🙃🙃 λem [ nm ]; Thermal, photophysical, and electrochemical properties of these compounds.
A31: 32 | B31: (10^-9.0) * Meter^(1.0) | C31: λem | D31: https://doi.org/10.1016/j.dyepig.2019.107957 | E31: toluene | F31: 594 | G31: C1=CC(=CC2=C1C1=NC3=CC(=C(C=C3N=C1C1=C2C=C(C=C1)C1=CC=C(N(C2=CC=C(C=C2)OC)C2=CC=C(C=C2)OC)C=C1)C1=CC=C(N(C2=CC=C(C=C2)OC)C2=CC=C(C=C2)OC)C=C1)C1=CC=C(N(C2=CC=C(C=C2)OC)C2=CC=C(C=C2)OC)C=C1)C1=CC=C(N(C2=CC=C(C=C2)OC)C2=CC=C(C=C2)OC)C=C1 | H31: 0 | I31: 594 , 626 , 596 Measured in toluene at 300 K . Measured in thin films on quartz substrate at 300 K . Measured in doped films on quartz substrate at 300 K . 🙃🙃🙃🙃 DBP -4MOTPA 🙃🙃🙃🙃 λem [ nm ]; Thermal, photophysical, and electrochemical properties of these compounds.
A32: 34 | B32: (10^-9.0) * Meter^(1.0) | C32: λems | D32: https://doi.org/10.1016/j.orgel.2017.06.034 | E32: toluene | F32: 715 | G32: COC1=CC=C(C=C1)N(C1=CC=C(C=C1)C1=CC=2C(C3=CC=C(C=C3C(C2C=C1)=O)C1=CC=C(C=C1)N(C1=CC=C(C=C1)OC)C1=CC=C(C=C1)OC)=O)C1=CC=C(C=C1)OC | H32: 0 | I32: 715 Measured in deposited films at 300 K . 🙃🙃🙃🙃 MPPA - Cz 🙃🙃🙃🙃 388 🙃🙃🙃🙃 345,379 , 487 🙃🙃🙃🙃 λems [ nm ]; Physical properties of MPPA, MPPA-Cz and MPPA-3Cz.
A33: 35 | B33: (10^-9.0) * Meter^(1.0) | C33: λems | D33: https://doi.org/10.1016/j.orgel.2017.06.034 | E33: toluene | F33: 667 | G33: COC1=CC=C(C=C1)N(C1=CC=C(C=C1)C1=CC=2C(C3=CC=C(C=C3C(C2C=C1)=O)C1=CC=C(C=C1)N(C1=CC=C(C=C1)OC)C1=CC=C(C=C1)OC)=O)C1=CC=C(C=C1)OC | H33: 0 | I33: 667 Measured in toluene at 300 K . 🙃🙃🙃🙃 MPPA -3Cz 🙃🙃🙃🙃 427 🙃🙃🙃🙃 265,294,330 🙃🙃🙃🙃 λems [ nm ]; Physical properties of MPPA, MPPA-Cz and MPPA-3Cz.
A34: 36 | B34: (10^-9.0) * Meter^(1.0) | C34: λems | D34: https://doi.org/10.1016/j.orgel.2017.06.034 | E34: toluene | F34: 708 | G34: COC1=CC=C(C=C1)N(C1=CC=C(C=C1)C1=CC=2C(C3=CC=C(C=C3C(C2C=C1)=O)C1=CC=C(C=C1)N(C1=CC=C(C=C1)OC)C1=CC=C(C=C1)OC)=O)C1=CC=C(C=C1)OC | H34: 0 | I34: 708 Measured in deposited films at 300 K . 🙃🙃🙃🙃 MPPA -3Cz 🙃🙃🙃🙃 427 🙃🙃🙃🙃 342,479,497 🙃🙃🙃🙃 λems [ nm ]; Physical properties of MPPA, MPPA-Cz and MPPA-3Cz.
A35: 39 | B35: (10^-9.0) * Meter^(1.0) | C35: λem | D35: https://doi.org/10.1016/j.dyepig.2023.111503 | E35: toluene | F35: 520 | G35: C1(=CC=CC=C1)N(C=1C=CC=2N(C3=CC=C(C=C3C2C1)N(C1=CC=CC=C1)C1=CC=CC=C1)C=1C=CC=2C(C3=CC=C(C=C3N(C2C1)C1=CC=CC=C1)N1C2=CC=C(C=C2C=2C=C(C=CC12)N(C1=CC=CC=C1)C1=CC=CC=C1)N(C1=CC=CC=C1)C1=CC=CC=C1)=O)C1=CC=CC=C1 | H35: 0 | I35: 520 / 535 🙃🙃🙃🙃 3,6 - DPCz - AD 🙃🙃🙃🙃 λem / λem [ nm ] ; Absorption and fluorescence peak wavelengths in toluene solutions at RT . ; Fluorescence wavelength in doped film in PPF .; The experimentally obtained basic parameters of,6-DPCz-AD.
A36: 40 | B36: (10^-9.0) * Meter^(1.0) | C36: λem | D36: https://doi.org/10.1016/j.cclet.2023.108385 | E36: water | F36: 515 | G36: C1(=CC=CC=C1)N(C1=CC=CC=C1)C1=CC=2C(C3=CC(=CC=C3C2C=C1)N(C1=CC=CC=C1)C1=CC=CC=C1)(C)C | H36: 0 | I36: 515 🙃🙃🙃🙃 2 🙃🙃🙃🙃 λem ( nm ); A summary of properties of organic LPL materials.
A37: 41 | B37: (10^-9.0) * Meter^(1.0) | C37: λem | D37: https://doi.org/10.1016/j.cclet.2023.108385 | E37: water | F37: 530 | G37: C1(=CC=CC=C1)N(C1=CC=CC=C1)C1=CC=2C(C3=CC(=CC=C3C2C=C1)N(C1=CC=CC=C1)C1=CC=CC=C1)(C)C | H37: 0 | I37: 530 🙃🙃🙃🙃 12 🙃🙃🙃🙃 λem ( nm ); A summary of properties of organic LPL materials.
A38: 42 | B38: (10^-9.0) * Meter^(1.0) | C38: λem | D38: https://doi.org/10.1016/j.dyepig.2020.108521 | E38: toluene | F38: 451 | G38: C1=CC=CC=2C3=CC=CC=C3N(C12)C1=CC=C(C=C1)C1=C(C(=NC(=C1C#N)C)C)C#N | H38: 0 | I38: 451 / 445 🙃🙃🙃🙃 λem / ( nm ) Recorded in dilute toluene ( 10−5 M ) . Recorded in doped film ( 10 wt % in PPF ) . 🙃🙃🙃🙃 Me - Cz; Data of simulation, photophysical and electrochemical properties.
A39: 43 | B39: (10^-9.0) * Meter^(1.0) | C39: λem | D39: https://doi.org/10.1016/j.dyepig.2020.108521 | E39: toluene | F39: 509 | G39: COC=1C=CC=2N(C3=CC=CC=C3C2C1)C1=CC=C(C=C1)C1=C(C(=NC(=C1C#N)C)C)C#N | H39: 0 | I39: 509 / 497 🙃🙃🙃🙃 λem / ( nm ) Recorded in dilute toluene ( 10−5 M ) . Recorded in doped film ( 10 wt % in PPF ) . 🙃🙃🙃🙃 Me - MOC; Data of simulation, photophysical and electrochemical properties.
A40: 44 | B40: (10^-9.0) * Meter^(1.0) | C40: λem | D40: https://doi.org/10.1016/j.dyepig.2020.108521 | E40: toluene | F40: 518 | G40: COC=1C=CC=2N(C3=CC=C(C=C3C2C1)OC)C1=CC=C(C=C1)C1=C(C(=NC(=C1C#N)C)C)C#N | H40: 0 | I40: 518 / 516 🙃🙃🙃🙃 λem / ( nm ) Recorded in dilute toluene ( 10−5 M ) . Recorded in doped film ( 10 wt % in PPF ) . 🙃🙃🙃🙃 Me - DOC; Data of simulation, photophysical and electrochemical properties.
...

Sheet 1_drop_film
A1: _id | B1: units | C1: specifier | D1: doi | E1: solvent | F1: standard_value | G1: smiles | H1: corrected | I1: context | J1: url | K1: lowered context | L1: contain
A2: 0 | B2: (10^-9.0) * Meter^(1.0) | C2: λema | D2: https://doi.org/10.1016/j.cej.2022.135775 | E2: toluene | F2: 638 | G2: N1=CC=C(C=C1)C=1C=C2N=C3C(=NC2=CC1C1=CC=NC=C1)C=1C=CC(=C2C=CC=C3C12)N1C2=CC=CC=C2OC=2C=CC=CC12 | H2: 1 | I2: 638 🙃🙃🙃🙃 pDPAPQ - PXZ 🙃🙃🙃🙃 λema [ nm ]; Summary of the photophysical properties of pDPAPQ-PXZ and pDPBPZ-PXZ. | J2: =HYPERLINK($D2, "link") -> link | K2: =LOWER($I2) -> 638 🙃🙃🙃🙃 pdpapq - pxz 🙃🙃🙃🙃 λema [ nm ]; summary of the photophysical properties of pdpapq-pxz and pdpbpz-pxz. | L2: {=OR(ISNUMBER(SEARCH('0_origin'!$O$2:$O$15, K2)))} -> FALSE
A3: 1 | B3: (10^-9.0) * Meter^(1.0) | C3: λema | D3: https://doi.org/10.1016/j.cej.2022.135775 | E3: toluene | F3: 639 | G3: N1=CC=C(C=C1)C=1C=C2N=C3C4=C(C5=C(C3=NC2=CC1C1=CC=NC=C1)C=CC(=C5)N5C1=CC=CC=C1OC=1C=CC=CC51)C=CC=C4 | H3: 1 | I3: 639 🙃🙃🙃🙃 pDPBPZ - PXZ 🙃🙃🙃🙃 λema [ nm ]; Summary of the photophysical properties of pDPAPQ-PXZ and pDPBPZ-PXZ. | J3: =HYPERLINK($D3, "link") -> link | K3: =LOWER($I3) -> 639 🙃🙃🙃🙃 pdpbpz - pxz 🙃🙃🙃🙃 λema [ nm ]; summary of the photophysical properties of pdpapq-pxz and pdpbpz-pxz. | L3: {=OR(ISNUMBER(SEARCH('0_origin'!$O$2:$O$15, K3)))} -> FALSE
A4: 2 | B4: (10^-9.0) * Meter^(1.0) | C4: λem | D4: https://doi.org/10.1016/j.dyepig.2023.111250 | E4: toluene | F4: 465 | G4: C1(=CC=CC=C1)C1=NC(=NC(=N1)C1=CC=CC=C1)C1=C(C=CC=C1)N1C2=CC=CC=C2C=2C=CC=CC12 | H4: 1 | I4: 402 🙃🙃🙃🙃 oCzTrz 🙃🙃🙃🙃 λem ( nm ) ; Wavelength of the singlet emission at the onset position .; Summary of the electrochemical and photophysical properties of oCzTrz and PhoCzTrz. | J4: =HYPERLINK($D4, "link") -> link | K4: =LOWER($I4) -> 402 🙃🙃🙃🙃 ocztrz 🙃🙃🙃🙃 λem ( nm ) ; wavelength of the singlet emission at the onset position .; summary of the electrochemical and photophysical properties of ocztrz and phocztrz. | L4: {=OR(ISNUMBER(SEARCH('0_origin'!$O$2:$O$15, K4)))} -> FALSE
A5: 4 | B5: (10^-9.0) * Meter^(1.0) | C5: λPL | D5: https://doi.org/10.1016/j.jphotochem.2024.116046 | E5: toluene | F5: 440 | G5: C(C)(C)(C)C=1C=CC=2N(C3=CC=C(C=C3C2C1)C(C)(C)C)CCCCCCCCC1(C2=CC=CC=C2C=2C=CC(=CC12)C1=C2C=CC=CC2=C(C2=CC=CC=C12)C1=CC=C(C#N)C=C1)CCCCCCCCN1C2=CC=C(C=C2C=2C=C(C=CC12)C(C)(C)C)C(C)(C)C | H5: 0 | I5: 440 / 449 🙃🙃🙃🙃 FAnCN 🙃🙃🙃🙃 λPL ( nm ) sola / filmb; The physical and photophysical data of the emitters. | J5: =HYPERLINK($D5, "link") -> link | K5: =LOWER($I5) -> 440 / 449 🙃🙃🙃🙃 fancn 🙃🙃🙃🙃 λpl ( nm ) sola / filmb; the physical and photophysical data of the emitters. | L5: {=OR(ISNUMBER(SEARCH('0_origin'!$O$2:$O$15, K5)))} -> FALSE
A6: 5 | B6: (10^-9.0) * Meter^(1.0) | C6: λPL | D6: https://doi.org/10.1016/j.jphotochem.2024.116046 | E6: toluene | F6: 424 | G6: C(C)(C)(C)C=1C=CC=2N(C3=CC=C(C=C3C2C1)C(C)(C)C)CCCCCCCCC1(C2=CC=CC=C2C=2C=CC(=CC12)C1=CC2=C3C=CC=CC3=C(C=C2C=2C=CC=CC12)C1=CC=C(C#N)C=C1)CCCCCCCCN1C2=CC=C(C=C2C=2C=C(C=CC12)C(C)(C)C)C(C)(C)C | H6: 0 | I6: 424 / 439 🙃🙃🙃🙃 FCsCN 🙃🙃🙃🙃 λPL ( nm ) sola / filmb; The physical and photophysical data of the emitters. | J6: =HYPERLINK($D6, "link") -> link | K6: =LOWER($I6) -> 424 / 439 🙃🙃🙃🙃 fcscn 🙃🙃🙃🙃 λpl ( nm ) sola / filmb; the physical and photophysical data of the emitters. | L6: {=OR(ISNUMBER(SEARCH('0_origin'!$O$2:$O$15, K6)))} -> FALSE
A7: 6 | B7: (10^-9.0) * Meter^(1.0) | C7: λem | D7: https://doi.org/10.1016/j.dyepig.2021.109649 | E7: toluene | F7: 536 | G7: CC1(C2=CC=CC=C2N(C=2C=CC=CC12)C1=CC=C(C=C1)C(=O)C1=CC=C(C=C1)SC1=CC=CC=C1)C | H7: 0 | I7: 536 🙃🙃🙃🙃 PT - BZ - DMAC 🙃🙃🙃🙃 λem [ nm ] ; Absorption and PL peak wavelengths in dilute toluene solutions at RT .; Summary of physical parameters of PT-BZ-DMAC and PS-BZ-DMAC. | J7: =HYPERLINK($D7, "link") -> link | K7: =LOWER($I7) -> 536 🙃🙃🙃🙃 pt - bz - dmac 🙃🙃🙃🙃 λem [ nm ] ; absorption and pl peak wavelengths in dilute toluene solutions at rt .; summary of physical parameters of pt-bz-dmac and ps-bz-dmac. | L7: {=OR(ISNUMBER(SEARCH('0_origin'!$O$2:$O$15, K7)))} -> TRUE
A8: 7 | B8: (10^-9.0) * Meter^(1.0) | C8: λem | D8: https://doi.org/10.1016/j.dyepig.2021.109649 | E8: toluene | F8: 574 | G8: CC1(C2=CC=CC=C2N(C=2C=CC=CC12)C1=CC=C(C=C1)C(=O)C1=CC=C(C=C1)S(=O)(=O)C1=CC=CC=C1)C | H8: 0 | I8: 574 🙃🙃🙃🙃 PS - BZ - DMAC 🙃🙃🙃🙃 λem [ nm ] ; Absorption and PL peak wavelengths in dilute toluene solutions at RT .; Summary of physical parameters of PT-BZ-DMAC and PS-BZ-DMAC. | J8: =HYPERLINK($D8, "link") -> link | K8: =LOWER($I8) -> 574 🙃🙃🙃🙃 ps - bz - dmac 🙃🙃🙃🙃 λem [ nm ] ; absorption and pl peak wavelengths in dilute toluene solutions at rt .; summary of physical parameters of pt-bz-dmac and ps-bz-dmac. | L8: {=OR(ISNUMBER(SEARCH('0_origin'!$O$2:$O$15, K8)))} -> TRUE
A9: 8 | B9: (10^-9.0) * Meter^(1.0) | C9: λPL | D9: https://doi.org/10.1016/j.jlumin.2021.118683 | E9: toluene | F9: 654 | G9: C(C)(C)C1=C(C(=CC=C1)C(C)C)N1C(C2=CC(=CC=3C2=C(C1=O)C=C(C3)N3C=1C=CC=CC1C(C1=CC=CC=C31)(C)C)N3C=1C=CC=CC1C(C1=CC=CC=C31)(C)C)=O | H9: 0 | I9: 654 / 646 / 618 Measured in toluene solutions ( 1 × 10−5 M ) . Measured in neat film . Measured in doped mCPCN film . 🙃🙃🙃🙃 2DN 🙃🙃🙃🙃 λPL [ nm ]; Summaries of physical data of 2DN and 2PN. | J9: =HYPERLINK($D9, "link") -> link | K9: =LOWER($I9) -> 654 / 646 / 618 measured in toluene solutions ( 1 × 10−5 m ) . measured in neat film . measured in doped mcpcn film . 🙃🙃🙃🙃 2dn 🙃🙃🙃🙃 λpl [ nm ]; summaries of physical data of 2dn and 2pn. | L9: {=OR(ISNUMBER(SEARCH('0_origin'!$O$2:$O$15, K9)))} -> TRUE
A10: 9 | B10: (10^-9.0) * Meter^(1.0) | C10: λPL | D10: https://doi.org/10.1016/j.jlumin.2021.118683 | E10: toluene | F10: 755 | G10: C(C)(C)C1=C(C(=CC=C1)C(C)C)N1C(C2=CC(=CC=3C2=C(C1=O)C=C(C3)N3C1=CC=CC=C1OC=1C=CC=CC31)N3C1=CC=CC=C1OC=1C=CC=CC31)=O | H10: 0 | I10: 755 / 725 / 650 Measured in toluene solutions ( 1 × 10−5 M ) . Measured in neat film . Measured in doped mCPCN film . 🙃🙃🙃🙃 2PN 🙃🙃🙃🙃 λPL [ nm ]; Summaries of physical data of 2DN and 2PN. | J10: =HYPERLINK($D10, "link") -> link | K10: =LOWER($I10) -> 755 / 725 / 650 measured in toluene solutions ( 1 × 10−5 m ) . measured in neat film . measured in doped mcpcn film . 🙃🙃🙃🙃 2pn 🙃🙃🙃🙃 λpl [ nm ]; summaries of physical data of 2dn and 2pn. | L10: {=OR(ISNUMBER(SEARCH('0_origin'!$O$2:$O$15, K10)))} -> TRUE
A11: 11 | B11: (10^-9.0) * Meter^(1.0) | C11: PL | D11: https://doi.org/10.1016/j.dyepig.2024.112417 | E11: toluene | F11: 440 | G11: C(C)(C)(C)C1=CC=C(C=C1)N(C1=CC=C(C=C1)C=1N(C(=C(N1)C#N)C#N)C)C1=CC=C(C=C1)C(C)(C)C | H11: 0 | I11: 440 / 463 🙃🙃🙃🙃 DCI - TPA 🙃🙃🙃🙃 PL / PL ( nm ) ; Measured in toluene solution . ; Measured in neat films .; Photophysical, electrochemical and thermal properties of the compounds. | J11: =HYPERLINK($D11, "link") -> link | K11: =LOWER($I11) -> 440 / 463 🙃🙃🙃🙃 dci - tpa 🙃🙃🙃🙃 pl / pl ( nm ) ; measured in toluene solution . ; measured in neat films .; photophysical, electrochemical and thermal properties of the compounds. | L11: {=OR(ISNUMBER(SEARCH('0_origin'!$O$2:$O$15, K11)))} -> TRUE
A12: 13 | B12: (10^-9.0) * Meter^(1.0) | C12: PL | D12: https://doi.org/10.1016/j.dyepig.2024.112417 | E12: toluene | F12: 457 | G12: C(C)(C)(C)C1=CC=C(C=C1)N(C1=CC=C(C=C1)C1=NC2=C(N1C)C=C(C(=C2)C#N)C#N)C2=CC=C(C=C2)C(C)(C)C | H12: 0 | I12: 457 / 460 🙃🙃🙃🙃 DCBI - TPA 🙃🙃🙃🙃 PL / PL ( nm ) ; Measured in toluene solution . ; Measured in neat films .; Photophysical, electrochemical and thermal properties of the compounds. | J12: =HYPERLINK($D12, "link") -> link | K12: =LOWER($I12) -> 457 / 460 🙃🙃🙃🙃 dcbi - tpa 🙃🙃🙃🙃 pl / pl ( nm ) ; measured in toluene solution . ; measured in neat films .; photophysical, electrochemical and thermal properties of the compounds. | L12: {=OR(ISNUMBER(SEARCH('0_origin'!$O$2:$O$15, K12)))} -> TRUE
A13: 14 | B13: (10^-9.0) * Meter^(1.0) | C13: λem | D13: https://doi.org/10.1016/j.cej.2020.126173 | E13: toluene | F13: 479 | G13: C1(=CC=CC=C1)C1=NC(=NC(=N1)C1=CC=CC=C1)C1=C(C=CC=C1)N1C=2C=CC=CC2C=2C=CC3=C(C12)C1=CC=CC=C1C31C3=CC=CC=C3C=3C=CC=CC31 | H13: 0 | I13: 479 🙃🙃🙃🙃 SF34oTz 🙃🙃🙃🙃 λem ( nm ) c ; Emission peaks in toluene solution ( 1 * 10−5 M ) .; Thermal, electrochemical, and photophysical data of SFxoTzs. | J13: =HYPERLINK($D13, "link") -> link | K13: =LOWER($I13) -> 479 🙃🙃🙃🙃 sf34otz 🙃🙃🙃🙃 λem ( nm ) c ; emission peaks in toluene solution ( 1 * 10−5 m ) .; thermal, electrochemical, and photophysical data of sfxotzs. | L13: {=OR(ISNUMBER(SEARCH('0_origin'!$O$2:$O$15, K13)))} -> TRUE
... A514: 645 | B514: (10^-9.0) * Meter^(1.0) | C514: λPL | D514: https://doi.org/10.1039/C4TC02547D | E514: toluene | F514: 405 | G514: C(CCC)C1(C2=CC(=CC=C2C=2C=CC(=CC12)C#CC1=CC=C2C=3C=CC(=CC3C(C2=C1)(CCC)CCC)C#N)C#CC1=CC=C2C=3C=CC(=CC3C(C2=C1)(CCC)CCC)C#N)CCCC | H514: 1 | I514: 434 , 413 🙃🙃🙃🙃 C3FLA -2 🙃🙃🙃🙃 λ PL [ nm ]; Table 1 Thermal, photophysical, and electrochemical characteristics of the novel deep-blue emitter, C3FLA-2, compared with those of the deep-blue emitters C2FLA-1 and MDP3FL | J514: =HYPERLINK($D514, "link") -> link | K514: =LOWER($I514) -> 434 , 413 🙃🙃🙃🙃 c3fla -2 🙃🙃🙃🙃 λ pl [ nm ]; table 1 thermal, photophysical, and electrochemical characteristics of the novel deep-blue emitter, c3fla-2, compared with those of the deep-blue emitters c2fla-1 and mdp3fl | L514: {=OR(ISNUMBER(SEARCH('0_origin'!$O$2:$O$15, K514)))} -> FALSE

Sheet 2_wiley_tier_b_added
A1: _id | B1: units | C1: specifier | D1: doi | E1: solvent | F1: standard_value | G1: smiles | H1: corrected | I1: context | J1: url | K1: lowered context | L1: contain
A2: 0 | B2: (10^-9.0) * Meter^(1.0) | C2: λema | D2: https://doi.org/10.1016/j.cej.2022.135775 | E2: toluene | F2: 638 | G2: N1=CC=C(C=C1)C=1C=C2N=C3C(=NC2=CC1C1=CC=NC=C1)C=1C=CC(=C2C=CC=C3C12)N1C2=CC=CC=C2OC=2C=CC=CC12 | H2: 1 | I2: 638 🙃🙃🙃🙃 pDPAPQ - PXZ 🙃🙃🙃🙃 λema [ nm ]; Summary of the photophysical properties of pDPAPQ-PXZ and pDPBPZ-PXZ.
A3: 1 | B3: (10^-9.0) * Meter^(1.0) | C3: λema | D3: https://doi.org/10.1016/j.cej.2022.135775 | E3: toluene | F3: 639 | G3: N1=CC=C(C=C1)C=1C=C2N=C3C4=C(C5=C(C3=NC2=CC1C1=CC=NC=C1)C=CC(=C5)N5C1=CC=CC=C1OC=1C=CC=CC51)C=CC=C4 | H3: 1 | I3: 639 🙃🙃🙃🙃 pDPBPZ - PXZ 🙃🙃🙃🙃 λema [ nm ]; Summary of the photophysical properties of pDPAPQ-PXZ and pDPBPZ-PXZ.
A4: 2 | B4: (10^-9.0) * Meter^(1.0) | C4: λem | D4: https://doi.org/10.1016/j.dyepig.2023.111250 | E4: toluene | F4: 465 | G4: C1(=CC=CC=C1)C1=NC(=NC(=N1)C1=CC=CC=C1)C1=C(C=CC=C1)N1C2=CC=CC=C2C=2C=CC=CC12 | H4: 1 | I4: 402 🙃🙃🙃🙃 oCzTrz 🙃🙃🙃🙃 λem ( nm ) ; Wavelength of the singlet emission at the onset position .; Summary of the electrochemical and photophysical properties of oCzTrz and PhoCzTrz.
A5: 4 | B5: (10^-9.0) * Meter^(1.0) | C5: λPL | D5: https://doi.org/10.1016/j.jphotochem.2024.116046 | E5: toluene | F5: 440 | G5: C(C)(C)(C)C=1C=CC=2N(C3=CC=C(C=C3C2C1)C(C)(C)C)CCCCCCCCC1(C2=CC=CC=C2C=2C=CC(=CC12)C1=C2C=CC=CC2=C(C2=CC=CC=C12)C1=CC=C(C#N)C=C1)CCCCCCCCN1C2=CC=C(C=C2C=2C=C(C=CC12)C(C)(C)C)C(C)(C)C | H5: 0 | I5: 440 / 449 🙃🙃🙃🙃 FAnCN 🙃🙃🙃🙃 λPL ( nm ) sola / filmb; The physical and photophysical data of the emitters.
A6: 5 | B6: (10^-9.0) * Meter^(1.0) | C6: λPL | D6: https://doi.org/10.1016/j.jphotochem.2024.116046 | E6: toluene | F6: 424 | G6: C(C)(C)(C)C=1C=CC=2N(C3=CC=C(C=C3C2C1)C(C)(C)C)CCCCCCCCC1(C2=CC=CC=C2C=2C=CC(=CC12)C1=CC2=C3C=CC=CC3=C(C=C2C=2C=CC=CC12)C1=CC=C(C#N)C=C1)CCCCCCCCN1C2=CC=C(C=C2C=2C=C(C=CC12)C(C)(C)C)C(C)(C)C | H6: 0 | I6: 424 / 439 🙃🙃🙃🙃 FCsCN 🙃🙃🙃🙃 λPL ( nm ) sola / filmb; The physical and photophysical data of the emitters.
A7: 6 | B7: (10^-9.0) * Meter^(1.0) | C7: λem | D7: https://doi.org/10.1016/j.dyepig.2021.109649 | E7: toluene | F7: 536 | G7: CC1(C2=CC=CC=C2N(C=2C=CC=CC12)C1=CC=C(C=C1)C(=O)C1=CC=C(C=C1)SC1=CC=CC=C1)C | H7: 0 | I7: 536 🙃🙃🙃🙃 PT - BZ - DMAC 🙃🙃🙃🙃 λem [ nm ] ; Absorption and PL peak wavelengths in dilute toluene solutions at RT .; Summary of physical parameters of PT-BZ-DMAC and PS-BZ-DMAC.
A8: 7 | B8: (10^-9.0) * Meter^(1.0) | C8: λem | D8: https://doi.org/10.1016/j.dyepig.2021.109649 | E8: toluene | F8: 574 | G8: CC1(C2=CC=CC=C2N(C=2C=CC=CC12)C1=CC=C(C=C1)C(=O)C1=CC=C(C=C1)S(=O)(=O)C1=CC=CC=C1)C | H8: 0 | I8: 574 🙃🙃🙃🙃 PS - BZ - DMAC 🙃🙃🙃🙃 λem [ nm ] ; Absorption and PL peak wavelengths in dilute toluene solutions at RT .; Summary of physical parameters of PT-BZ-DMAC and PS-BZ-DMAC.
A9: 8 | B9: (10^-9.0) * Meter^(1.0) | C9: λPL | D9: https://doi.org/10.1016/j.jlumin.2021.118683 | E9: toluene | F9: 654 | G9: C(C)(C)C1=C(C(=CC=C1)C(C)C)N1C(C2=CC(=CC=3C2=C(C1=O)C=C(C3)N3C=1C=CC=CC1C(C1=CC=CC=C31)(C)C)N3C=1C=CC=CC1C(C1=CC=CC=C31)(C)C)=O | H9: 0 | I9: 654 / 646 / 618 Measured in toluene solutions ( 1 × 10−5 M ) . Measured in neat film . Measured in doped mCPCN film . 🙃🙃🙃🙃 2DN 🙃🙃🙃🙃 λPL [ nm ]; Summaries of physical data of 2DN and 2PN.
A10: 9 | B10: (10^-9.0) * Meter^(1.0) | C10: λPL | D10: https://doi.org/10.1016/j.jlumin.2021.118683 | E10: toluene | F10: 755 | G10: C(C)(C)C1=C(C(=CC=C1)C(C)C)N1C(C2=CC(=CC=3C2=C(C1=O)C=C(C3)N3C1=CC=CC=C1OC=1C=CC=CC31)N3C1=CC=CC=C1OC=1C=CC=CC31)=O | H10: 0 | I10: 755 / 725 / 650 Measured in toluene solutions ( 1 × 10−5 M ) . Measured in neat film . Measured in doped mCPCN film . 🙃🙃🙃🙃 2PN 🙃🙃🙃🙃 λPL [ nm ]; Summaries of physical data of 2DN and 2PN.
A11: 11 | B11: (10^-9.0) * Meter^(1.0) | C11: PL | D11: https://doi.org/10.1016/j.dyepig.2024.112417 | E11: toluene | F11: 440 | G11: C(C)(C)(C)C1=CC=C(C=C1)N(C1=CC=C(C=C1)C=1N(C(=C(N1)C#N)C#N)C)C1=CC=C(C=C1)C(C)(C)C | H11: 0 | I11: 440 / 463 🙃🙃🙃🙃 DCI - TPA 🙃🙃🙃🙃 PL / PL ( nm ) ; Measured in toluene solution . ; Measured in neat films .; Photophysical, electrochemical and thermal properties of the compounds.
A12: 13 | B12: (10^-9.0) * Meter^(1.0) | C12: PL | D12: https://doi.org/10.1016/j.dyepig.2024.112417 | E12: toluene | F12: 457 | G12: C(C)(C)(C)C1=CC=C(C=C1)N(C1=CC=C(C=C1)C1=NC2=C(N1C)C=C(C(=C2)C#N)C#N)C2=CC=C(C=C2)C(C)(C)C | H12: 0 | I12: 457 / 460 🙃🙃🙃🙃 DCBI - TPA 🙃🙃🙃🙃 PL / PL ( nm ) ; Measured in toluene solution . ; Measured in neat films .; Photophysical, electrochemical and thermal properties of the compounds.
A13: 14 | B13: (10^-9.0) * Meter^(1.0) | C13: λem | D13: https://doi.org/10.1016/j.cej.2020.126173 | E13: toluene | F13: 479 | G13: C1(=CC=CC=C1)C1=NC(=NC(=N1)C1=CC=CC=C1)C1=C(C=CC=C1)N1C=2C=CC=CC2C=2C=CC3=C(C12)C1=CC=CC=C1C31C3=CC=CC=C3C=3C=CC=CC31 | H13: 0 | I13: 479 🙃🙃🙃🙃 SF34oTz 🙃🙃🙃🙃 λem ( nm ) c ; Emission peaks in toluene solution ( 1 * 10−5 M ) .; Thermal, electrochemical, and photophysical data of SFxoTzs.
... A514: 645 | B514: (10^-9.0) * Meter^(1.0) | C514: λPL | D514: https://doi.org/10.1039/C4TC02547D | E514: toluene | F514: 405 | G514: C(CCC)C1(C2=CC(=CC=C2C=2C=CC(=CC12)C#CC1=CC=C2C=3C=CC(=CC3C(C2=C1)(CCC)CCC)C#N)C#CC1=CC=C2C=3C=CC(=CC3C(C2=C1)(CCC)CCC)C#N)CCCC | H514: 1 | I514: 434 , 413 🙃🙃🙃🙃 C3FLA -2 🙃🙃🙃🙃 λ PL [ nm ]; Table 1 Thermal, photophysical, and electrochemical characteristics of the novel deep-blue emitter, C3FLA-2, compared with those of the deep-blue emitters C2FLA-1 and MDP3FL
A515: 700 | B515: (10^-9.0) * Meter^(1.0) | C515: λema | D515: https://doi.org/10.1002/adfm.202420489 | F515: 616 | G515: C1(=CC=CC=C1)N(C1=CC=C(C=C1)C1=CC2=C(C3=NC4=CC(=C(C=C4N=C3C3=C2C=CC=C3)C#N)C#N)C=C1)C1=CC=CC=C1 | I515: 616 🙃🙃🙃🙃 DCN - TPA 🙃🙃🙃🙃 Nema ) [ nm ]; Table 1. Summary of the photophysical properties of DCN-TPA and DCN-SAC.
A516: 701 | B516: (10^-9.0) * Meter^(1.0) | C516: λema | D516: https://doi.org/10.1002/adfm.202420489 | F516: 606 | G516: C1(=CC=CC=C1)N1C=2C=CC(=CC2C2(C3=CC=CC=C3C=3C=CC=CC23)C2=CC=CC=C12)C1=CC2=C(C3=NC4=CC(=C(C=C4N=C3C3=C2C=CC=C3)C#N)C#N)C=C1 | I516: 606 🙃🙃🙃🙃 DCN - SAC 🙃🙃🙃🙃 Nema ) [ nm ]; Table 1. Summary of the photophysical properties of DCN-TPA and DCN-SAC.
A517: 702 | B517: (10^-9.0) * Meter^(1.0) | C517: λema | D517: https://doi.org/10.1002/adom.202300368 | F517: 616 | G517: C1(=CC=CC=C1)N(C1=CC=C(C=C1)C1=CC2=C(C3=NC4=CC(=C(C=C4N=C3C3=C2C=CC=C3)C#N)C#N)C=C1)C1=CC=CC=C1 | I517: 616 🙃🙃🙃🙃 DCN - Ph - DPA 🙃🙃🙃🙃 Nema ) [ nm ]; Table 1. Summary of the photophysical properties of DCN-Ph-DPA and DCN-SP-DPA.
A518: 703 | B518: (10^-9.0) * Meter^(1.0) | C518: λema | D518: https://doi.org/10.1002/adom.202300368 | F518: 622 | G518: C1(=CC=CC=C1)N(C1=CC=2C3(C4=CC(=CC=C4C2C=C1)C1=CC2=C(C4=NC5=CC(=C(C=C5N=C4C4=C2C=CC=C4)C#N)C#N)C=C1)C1=CC=CC=C1C=1C=CC=CC13)C1=CC=CC=C1 | I518: 622 🙃🙃🙃🙃 DCN - SP - DPA 🙃🙃🙃🙃 Nema ) [ nm ]; Table 1. Summary of the photophysical properties of DCN-Ph-DPA and DCN-SP-DPA.
A519: 704 | B519: (10^-9.0) * Meter^(1.0) | C519: λem | D519: https://doi.org/10.1002/chem.202401250 | F519: 512 | G519: C1(=CC=CC=C1)C1=NC(=NC(=N1)C1=CC=CC=C1)C1=CC=C(C=C1)N1C=2C=CC(=CC2C(C2=CC(=CC=C12)C1=C(C=CC=C1)F)(C)C)C1=C(C=CC=C1)F | I519: 512 🙃🙃🙃🙃 2,7 - F - Ph - DMAC - TRZ 🙃🙃🙃🙃 Nem [ nm ]; ![](images/174f76d2eeac0b647d07111684f0bde2d1d8c111bcec618cdd15999d7652e4b9.jpg)
A520: 705 | B520: (10^-9.0) * Meter^(1.0) | C520: λem | D520: https://doi.org/10.1002/chem.202401250 | F520: 504 | G520: C1(=CC=CC=C1)C1=NC(=NC(=N1)C1=CC=CC=C1)C1=CC=C(C=C1)N1C=2C=CC(=CC2C(C2=CC(=CC=C12)C1=C(C=CC=C1)C(F)(F)F)(C)C)C1=C(C=CC=C1)C(F)(F)F | I520: 504 🙃🙃🙃🙃 2,7 - CF3 - Ph - DMAC - TRZ 🙃🙃🙃🙃 Nem [ nm ]; ![](images/174f76d2eeac0b647d07111684f0bde2d1d8c111bcec618cdd15999d7652e4b9.jpg)
A521: 706 | B521: (10^-9.0) * Meter^(1.0) | C521: λpLa | D521: https://doi.org/10.1002/adfm.202105805 | F521: 446 | G521: C1=CC=CC=2OC=3C=C(C=C4OC=5C=CC=CC5B(C34)C12)N1C=2C=CC=CC2C2=C3C(=C4N(C=5C=CC=CC5C4=C21)C2=CC=CC=C2)C2=C(O3)C=CC=C2 | I521: 446 🙃🙃🙃🙃 DBA - BFICz 🙃🙃🙃🙃 NpLa ) [ nm ]; Table 1. Photophysical properties of DBA-BFICz and DBA-BTICz.
A522: 707 | B522: (10^-9.0) * Meter^(1.0) | C522: λpLa | D522: https://doi.org/10.1002/adfm.202105805 | F522: 445 | G522: C1=CC=CC=2OC=3C=C(C=C4OC=5C=CC=CC5B(C34)C12)N1C=2C=CC=CC2C2=C3C(=C4N(C=5C=CC=CC5C4=C21)C2=CC=CC=C2)C2=C(S3)C=CC=C2 | I522: 445 🙃🙃🙃🙃 DBA - BTICz 🙃🙃🙃🙃 NpLa ) [ nm ]; Table 1. Photophysical properties of DBA-BFICz and DBA-BTICz.
A523: 708 | B523: (10^-9.0) * Meter^(1.0) | C523: λemb | D523: https://doi.org/10.1002/adom.201700145 | E523: Cyclohexane | F523: 625 | G523: CC1(C2=CC=CC=C2N(C=2C=CC=CC12)C1=CC=C(C=C1)C1=C2C=CC=CC2=C(C2=NSN=C21)C2=CC=C(C=C2)N2C=1C=CC=CC1C(C1=CC=CC=C21)(C)C)C | I523: 625 🙃🙃🙃🙃 Cyclohexane 🙃🙃🙃🙃 Nemb ) [ nm ]; Table 1. Photophysical properties of NZ2AC in different solvents.
A524: 709 | B524: (10^-9.0) * Meter^(1.0) | C524: λemb | D524: https://doi.org/10.1002/adom.201700145 | E524: Toluene | F524: 631 | G524: CC1(C2=CC=CC=C2N(C=2C=CC=CC12)C1=CC=C(C=C1)C1=C2C=CC=CC2=C(C2=NSN=C21)C2=CC=C(C=C2)N2C=1C=CC=CC1C(C1=CC=CC=C21)(C)C)C | I524: 631 🙃🙃🙃🙃 Toluene 🙃🙃🙃🙃 Nemb ) [ nm ]; Table 1. Photophysical properties of NZ2AC in different solvents.
A525: 710 | B525: (10^-9.0) * Meter^(1.0) | C525: λemb | D525: https://doi.org/10.1002/adom.201700145 | E525: Chloroform | F525: 663 | G525: CC1(C2=CC=CC=C2N(C=2C=CC=CC12)C1=CC=C(C=C1)C1=C2C=CC=CC2=C(C2=NSN=C21)C2=CC=C(C=C2)N2C=1C=CC=CC1C(C1=CC=CC=C21)(C)C)C | I525: 663 🙃🙃🙃🙃 Chloroform 🙃🙃🙃🙃 Nemb ) [ nm ]; Table 1. Photophysical properties of NZ2AC in different solvents.
A526: 711 | B526: (10^-9.0) * Meter^(1.0) | C526: λemb | D526: https://doi.org/10.1002/adom.201700145 | E526: Tetrahydrofuran | F526: 668 | G526: CC1(C2=CC=CC=C2N(C=2C=CC=CC12)C1=CC=C(C=C1)C1=C2C=CC=CC2=C(C2=NSN=C21)C2=CC=C(C=C2)N2C=1C=CC=CC1C(C1=CC=CC=C21)(C)C)C | I526: 668 🙃🙃🙃🙃 Tetrahydrofuran 🙃🙃🙃🙃 Nemb ) [ nm ]; Table 1. Photophysical properties of NZ2AC in different solvents.
A527: 712 | B527: (10^-9.0) * Meter^(1.0) | C527: λemb | D527: https://doi.org/10.1002/adom.201700145 | E527: Dichloromethane | F527: 663 | G527: CC1(C2=CC=CC=C2N(C=2C=CC=CC12)C1=CC=C(C=C1)C1=C2C=CC=CC2=C(C2=NSN=C21)C2=CC=C(C=C2)N2C=1C=CC=CC1C(C1=CC=CC=C21)(C)C)C | I527: 663 🙃🙃🙃🙃 Dichloromethane 🙃🙃🙃🙃 Nemb ) [ nm ]; Table 1. Photophysical properties of NZ2AC in different solvents.
A528: 713 | B528: (10^-9.0) * Meter^(1.0) | C528: λem | D528: https://doi.org/10.1002/ange.201600113 | E528: cyclohexane | F528: 457 | G528: CC(C1=CC2=C(N(C3=CC4=CC=C5C(N=C(C(C=CC(N6C7=C(C8=C6C=CC(C(C)(C)C)=C8)C=C(C(C)(C)C)C=C7)=C9)=C9C=C%10)C%10=N5)=C4C=C3)C%11=C2C=C(C(C)(C)C)C=C%11)C=C1)(C)C | H528: 1 | I528: 457 / 509 🙃🙃🙃🙃 t - BuCZ - DBPHZ 🙃🙃🙃🙃 Nem [ nm ] ( in c - hexl @ / in CBP filmb ); Table 1: Summary of properties of DBPHZs.
A529: 714 | B529: (10^-9.0) * Meter^(1.0) | C529: λMax. | D529: https://doi.org/10.1002/advs.201800436 | E529: toluene | F529: 612 | G529: C1=CC=CC=2OC3=CC=CC=C3N(C12)C=1C=CC2=C(C3=C(C4=NC5=C6C(=C7C(=C5N=C24)C=CC=N7)N=CC=C6)C=CC(=C3)N3C6=CC=CC=C6OC=6C=CC=CC36)C1 | H529: 1 | I529: 612 🙃🙃🙃🙃 DPXZ - BPPZ 🙃🙃🙃🙃 NMax . [ nm ] 🙃🙃🙃🙃 NMax . [ nm ]; Table 1. Summary of performances of red TADF OLEDs (ELmax≥670 nm) ).
A530: 715 | B530: (10^-9.0) * Meter^(1.0) | C530: PL | D530: https://doi.org/10.1002/adfm.202411957 | F530: 501 | G530: C1=CC=CC2=C1N1C3=C2C=CC=C3OC=3C=CC=CC13 | I530: 501 🙃🙃🙃🙃 1 🙃🙃🙃🙃 1 🙃🙃🙃🙃 PL [ nm ]; Table 1. Emission characteristics of emitters 1 and 2 doped (xwt-%) in the PPF films.
A531: 716 | B531: (10^-9.0) * Meter^(1.0) | C531: PL | D531: https://doi.org/10.1002/adfm.202411957 | F531: 506 | G531: C1=CC=CC2=C1N1C3=C2C=CC=C3OC=3C=CC=CC13 | I531: 506 🙃🙃🙃🙃 1 🙃🙃🙃🙃 20 🙃🙃🙃🙃 PL [ nm ]; Table 1. Emission characteristics of emitters 1 and 2 doped (xwt-%) in the PPF films.
A532: 717 | B532: (10^-9.0) * Meter^(1.0) | C532: PL | D532: https://doi.org/10.1002/adfm.202411957 | F532: 500 | G532: C1=CC=CC2=C1N1C3=C2C=CC=C3OC=3C=CC=CC13 | I532: 500 🙃🙃🙃🙃 2 🙃🙃🙃🙃 1 🙃🙃🙃🙃 PL [ nm ]; Table 1. Emission characteristics of emitters 1 and 2 doped (xwt-%) in the PPF films.
A533: 718 | B533: (10^-9.0) * Meter^(1.0) | C533: PL | D533: https://doi.org/10.1002/adfm.202411957 | F533: 508 | G533: C1=CC=CC2=C1N1C3=C2C=CC=C3OC=3C=CC=CC13 | I533: 508 🙃🙃🙃🙃 2 🙃🙃🙃🙃 20 🙃🙃🙃🙃 PL [ nm ]; Table 1. Emission characteristics of emitters 1 and 2 doped (xwt-%) in the PPF films.
A534: 719 | B534: (10^-9.0) * Meter^(1.0) | C534: λem | D534: https://doi.org/10.1002/adom.202002019 | E534: THF | F534: 510 | G534: O=C(C1=CC=C(N2C(C=CC=C3)=C3C4(C(C=CC=C5)=C5C6=C4C=CC=C6)C7=C2C=CC=C7)C=C1)C(C=C8C9=C%10C=CC=C9)=CC=C8N%10C(C=C%11)=CC=C%11N%12C%13=CC=CC=C%13C%14=C%12C=CC=C%14 | H534: 1 | I534: 510 🙃🙃🙃🙃 Nem [ nm ] 🙃🙃🙃🙃 solutiona ); Table 1. The photophysical data of DCB-BP-SFAC.
A535: 720 | B535: (10^-9.0) * Meter^(1.0) | C535: λema | D535: https://doi.org/10.1002/adfm.202304398 | E535: toluene | F535: 648 | G535: N#CC(C=C1N=C2C3=C4C=C(C5=CC=C(N(C6=CC=C(C(C=CC=C7)=C7C89C(C=CC=C%10)=C%10C%11=C9C=CC=C%11)C8=C6)C%12=CC=CC=C%12)C=C5)C=C3)=C(C#N)C=C1N=C2C%13=C4C=CC=C%13 | H535: 1 | I535: 648 🙃🙃🙃🙃 DCN - SPTPA 🙃🙃🙃🙃 Nema ) [ nm ]; Table 1. Summary of the photophysical properties of DCN-PhTPA and DCN-SPTPA.
A536: 721 | B536: (10^-9.0) * Meter^(1.0) | C536: λem | D536: https://doi.org/10.1002/adom.201600304 | E536: toluene | F536: 543 | G536: C1=CC=CC=2OC3=CC=CC=C3N(C12)C=1C=NC2=C3N=CC(=CC3=CC=C2C1)N1C2=CC=CC=C2OC=2C=CC=CC12 | H536: 1 | I536: 543 🙃🙃🙃🙃 m - PXZP 🙃🙃🙃🙃 Nem [ nm ] a ); Table 2. Physical properties of ±bx-PXZP.
A537: 722 | B537: (10^-9.0) * Meter^(1.0) | C537: λem | D537: https://doi.org/10.1002/adom.201600304 | E537: toluene | F537: 535 | G537: C1=CC=CC=2OC3=CC=CC=C3N(C12)C1=CC=NC2=C3N=CC=C(C3=CC=C12)N1C2=CC=CC=C2OC=2C=CC=CC12 | H537: 1 | I537: 535 🙃🙃🙃🙃 p - PXZP 🙃🙃🙃🙃 Nem [ nm ] a ); Table 2. Physical properties of ±bx-PXZP.
A538: 723 | B538: (10^-9.0) * Meter^(1.0) | C538: λem | D538: https://doi.org/10.1002/adom.201600304 | E538: toluene | F538: 554 | G538: C1=CC=CC=2OC3=CC=CC=C3N(C12)C1=NC2=C3N=C(C=CC3=CC=C2C=C1)N1C2=CC=CC=C2OC=2C=CC=CC12 | H538: 1 | I538: 535 🙃🙃🙃🙃 o - PXZP 🙃🙃🙃🙃 Nem [ nm ] a ); Table 2. Physical properties of ±bx-PXZP.
A539: 724 | B539: (10^-9.0) * Meter^(1.0) | C539: λem | D539: https://doi.org/10.1002/ange.201906575 | E539: toluene | F539: 607 | G539: C1=CC=NC2=C3C(=C4N=C5C6=C(C7=C(C5=NC4=C21)C=CC=C7)C=C(C=C6)N6C7=CC=CC=C7OC=7C=CC=CC67)C=CC=N3 | H539: 1 | I539: 607 🙃🙃🙃🙃 BPPZ - PXZ 🙃🙃🙃🙃 Nem [ nm ] ( b ]; Tabelle 1: Summary of physical properties of BPPZ-PXZ and mDPBPZ-PXZ.
A540: 725 | B540: (10^-9.0) * Meter^(1.0) | C540: λem | D540: https://doi.org/10.1002/ange.201906575 | F540: 638 | G540: N1=CC(=CC=C1)C=1C=C2N=C3C4=C(C5=C(C3=NC2=CC1C=1C=NC=CC1)C=CC(=C5)N5C1=CC=CC=C1OC=1C=CC=CC51)C=CC=C4 | I540: 638 🙃🙃🙃🙃 mDPBPZ - PXZ 🙃🙃🙃🙃 Nem [ nm ] ( b ]; Tabelle 1: Summary of physical properties of BPPZ-PXZ and mDPBPZ-PXZ.
...

Sheet 3_manual_smiles_added
A1: _id | B1: units | C1: specifier | D1: doi | E1: solvent | F1: standard_value | G1: smiles | H1: corrected | I1: context | J1: url | K1: lowered context | L1: contain
A2: 0 | B2: (10^-9.0) * Meter^(1.0) | C2: λema | D2: https://doi.org/10.1016/j.cej.2022.135775 | E2: toluene | F2: 638 | G2: N1=CC=C(C=C1)C=1C=C2N=C3C(=NC2=CC1C1=CC=NC=C1)C=1C=CC(=C2C=CC=C3C12)N1C2=CC=CC=C2OC=2C=CC=CC12 | H2: 1 | I2: 638 🙃🙃🙃🙃 pDPAPQ - PXZ 🙃🙃🙃🙃 λema [ nm ]; Summary of the photophysical properties of pDPAPQ-PXZ and pDPBPZ-PXZ.
A3: 1 | B3: (10^-9.0) * Meter^(1.0) | C3: λema | D3: https://doi.org/10.1016/j.cej.2022.135775 | E3: toluene | F3: 639 | G3: N1=CC=C(C=C1)C=1C=C2N=C3C4=C(C5=C(C3=NC2=CC1C1=CC=NC=C1)C=CC(=C5)N5C1=CC=CC=C1OC=1C=CC=CC51)C=CC=C4 | H3: 1 | I3: 639 🙃🙃🙃🙃 pDPBPZ - PXZ 🙃🙃🙃🙃 λema [ nm ]; Summary of the photophysical properties of pDPAPQ-PXZ and pDPBPZ-PXZ.
A4: 2 | B4: (10^-9.0) * Meter^(1.0) | C4: λem | D4: https://doi.org/10.1016/j.dyepig.2023.111250 | E4: toluene | F4: 465 | G4: C1(=CC=CC=C1)C1=NC(=NC(=N1)C1=CC=CC=C1)C1=C(C=CC=C1)N1C2=CC=CC=C2C=2C=CC=CC12 | H4: 1 | I4: 402 🙃🙃🙃🙃 oCzTrz 🙃🙃🙃🙃 λem ( nm ) ; Wavelength of the singlet emission at the onset position .; Summary of the electrochemical and photophysical properties of oCzTrz and PhoCzTrz.
A5: 4 | B5: (10^-9.0) * Meter^(1.0) | C5: λPL | D5: https://doi.org/10.1016/j.jphotochem.2024.116046 | E5: toluene | F5: 440 | G5: C(C)(C)(C)C=1C=CC=2N(C3=CC=C(C=C3C2C1)C(C)(C)C)CCCCCCCCC1(C2=CC=CC=C2C=2C=CC(=CC12)C1=C2C=CC=CC2=C(C2=CC=CC=C12)C1=CC=C(C#N)C=C1)CCCCCCCCN1C2=CC=C(C=C2C=2C=C(C=CC12)C(C)(C)C)C(C)(C)C | H5: 0 | I5: 440 / 449 🙃🙃🙃🙃 FAnCN 🙃🙃🙃🙃 λPL ( nm ) sola / filmb; The physical and photophysical data of the emitters.
A6: 5 | B6: (10^-9.0) * Meter^(1.0) | C6: λPL | D6: https://doi.org/10.1016/j.jphotochem.2024.116046 | E6: toluene | F6: 424 | G6: C(C)(C)(C)C=1C=CC=2N(C3=CC=C(C=C3C2C1)C(C)(C)C)CCCCCCCCC1(C2=CC=CC=C2C=2C=CC(=CC12)C1=CC2=C3C=CC=CC3=C(C=C2C=2C=CC=CC12)C1=CC=C(C#N)C=C1)CCCCCCCCN1C2=CC=C(C=C2C=2C=C(C=CC12)C(C)(C)C)C(C)(C)C | H6: 0 | I6: 424 / 439 🙃🙃🙃🙃 FCsCN 🙃🙃🙃🙃 λPL ( nm ) sola / filmb; The physical and photophysical data of the emitters.
A7: 6 | B7: (10^-9.0) * Meter^(1.0) | C7: λem | D7: https://doi.org/10.1016/j.dyepig.2021.109649 | E7: toluene | F7: 536 | G7: CC1(C2=CC=CC=C2N(C=2C=CC=CC12)C1=CC=C(C=C1)C(=O)C1=CC=C(C=C1)SC1=CC=CC=C1)C | H7: 0 | I7: 536 🙃🙃🙃🙃 PT - BZ - DMAC 🙃🙃🙃🙃 λem [ nm ] ; Absorption and PL peak wavelengths in dilute toluene solutions at RT .; Summary of physical parameters of PT-BZ-DMAC and PS-BZ-DMAC.
A8: 7 | B8: (10^-9.0) * Meter^(1.0) | C8: λem | D8: https://doi.org/10.1016/j.dyepig.2021.109649 | E8: toluene | F8: 574 | G8: CC1(C2=CC=CC=C2N(C=2C=CC=CC12)C1=CC=C(C=C1)C(=O)C1=CC=C(C=C1)S(=O)(=O)C1=CC=CC=C1)C | H8: 0 | I8: 574 🙃🙃🙃🙃 PS - BZ - DMAC 🙃🙃🙃🙃 λem [ nm ] ; Absorption and PL peak wavelengths in dilute toluene solutions at RT .; Summary of physical parameters of PT-BZ-DMAC and PS-BZ-DMAC.
A9: 8 | B9: (10^-9.0) * Meter^(1.0) | C9: λPL | D9: https://doi.org/10.1016/j.jlumin.2021.118683 | E9: toluene | F9: 654 | G9: C(C)(C)C1=C(C(=CC=C1)C(C)C)N1C(C2=CC(=CC=3C2=C(C1=O)C=C(C3)N3C=1C=CC=CC1C(C1=CC=CC=C31)(C)C)N3C=1C=CC=CC1C(C1=CC=CC=C31)(C)C)=O | H9: 0 | I9: 654 / 646 / 618 Measured in toluene solutions ( 1 × 10−5 M ) . Measured in neat film . Measured in doped mCPCN film . 🙃🙃🙃🙃 2DN 🙃🙃🙃🙃 λPL [ nm ]; Summaries of physical data of 2DN and 2PN.
A10: 9 | B10: (10^-9.0) * Meter^(1.0) | C10: λPL | D10: https://doi.org/10.1016/j.jlumin.2021.118683 | E10: toluene | F10: 755 | G10: C(C)(C)C1=C(C(=CC=C1)C(C)C)N1C(C2=CC(=CC=3C2=C(C1=O)C=C(C3)N3C1=CC=CC=C1OC=1C=CC=CC31)N3C1=CC=CC=C1OC=1C=CC=CC31)=O | H10: 0 | I10: 755 / 725 / 650 Measured in toluene solutions ( 1 × 10−5 M ) . Measured in neat film . Measured in doped mCPCN film . 🙃🙃🙃🙃 2PN 🙃🙃🙃🙃 λPL [ nm ]; Summaries of physical data of 2DN and 2PN.
A11: 11 | B11: (10^-9.0) * Meter^(1.0) | C11: PL | D11: https://doi.org/10.1016/j.dyepig.2024.112417 | E11: toluene | F11: 440 | G11: C(C)(C)(C)C1=CC=C(C=C1)N(C1=CC=C(C=C1)C=1N(C(=C(N1)C#N)C#N)C)C1=CC=C(C=C1)C(C)(C)C | H11: 0 | I11: 440 / 463 🙃🙃🙃🙃 DCI - TPA 🙃🙃🙃🙃 PL / PL ( nm ) ; Measured in toluene solution . ; Measured in neat films .; Photophysical, electrochemical and thermal properties of the compounds.
A12: 13 | B12: (10^-9.0) * Meter^(1.0) | C12: PL | D12: https://doi.org/10.1016/j.dyepig.2024.112417 | E12: toluene | F12: 457 | G12: C(C)(C)(C)C1=CC=C(C=C1)N(C1=CC=C(C=C1)C1=NC2=C(N1C)C=C(C(=C2)C#N)C#N)C2=CC=C(C=C2)C(C)(C)C | H12: 0 | I12: 457 / 460 🙃🙃🙃🙃 DCBI - TPA 🙃🙃🙃🙃 PL / PL ( nm ) ; Measured in toluene solution . ; Measured in neat films .; Photophysical, electrochemical and thermal properties of the compounds.
A13: 14 | B13: (10^-9.0) * Meter^(1.0) | C13: λem | D13: https://doi.org/10.1016/j.cej.2020.126173 | E13: toluene | F13: 479 | G13: C1(=CC=CC=C1)C1=NC(=NC(=N1)C1=CC=CC=C1)C1=C(C=CC=C1)N1C=2C=CC=CC2C=2C=CC3=C(C12)C1=CC=CC=C1C31C3=CC=CC=C3C=3C=CC=CC31 | H13: 0 | I13: 479 🙃🙃🙃🙃 SF34oTz 🙃🙃🙃🙃 λem ( nm ) c ; Emission peaks in toluene solution ( 1 * 10−5 M ) .; Thermal, electrochemical, and photophysical data of SFxoTzs.
... A514: 645 | B514: (10^-9.0) * Meter^(1.0) | C514: λPL | D514: https://doi.org/10.1039/C4TC02547D | E514: toluene | F514: 405 | G514: C(CCC)C1(C2=CC(=CC=C2C=2C=CC(=CC12)C#CC1=CC=C2C=3C=CC(=CC3C(C2=C1)(CCC)CCC)C#N)C#CC1=CC=C2C=3C=CC(=CC3C(C2=C1)(CCC)CCC)C#N)CCCC | H514: 1 | I514: 434 , 413 🙃🙃🙃🙃 C3FLA -2 🙃🙃🙃🙃 λ PL [ nm ]; Table 1 Thermal, photophysical, and electrochemical characteristics of the novel deep-blue emitter, C3FLA-2, compared with those of the deep-blue emitters C2FLA-1 and MDP3FL
A515: 700 | B515: (10^-9.0) * Meter^(1.0) | C515: λema | D515: https://doi.org/10.1002/adfm.202420489 | F515: 616 | G515: C1(=CC=CC=C1)N(C1=CC=C(C=C1)C1=CC2=C(C3=NC4=CC(=C(C=C4N=C3C3=C2C=CC=C3)C#N)C#N)C=C1)C1=CC=CC=C1 | I515: 616 🙃🙃🙃🙃 DCN - TPA 🙃🙃🙃🙃 Nema ) [ nm ]; Table 1. Summary of the photophysical properties of DCN-TPA and DCN-SAC.
A516: 701 | B516: (10^-9.0) * Meter^(1.0) | C516: λema | D516: https://doi.org/10.1002/adfm.202420489 | F516: 606 | G516: C1(=CC=CC=C1)N1C=2C=CC(=CC2C2(C3=CC=CC=C3C=3C=CC=CC23)C2=CC=CC=C12)C1=CC2=C(C3=NC4=CC(=C(C=C4N=C3C3=C2C=CC=C3)C#N)C#N)C=C1 | I516: 606 🙃🙃🙃🙃 DCN - SAC 🙃🙃🙃🙃 Nema ) [ nm ]; Table 1. Summary of the photophysical properties of DCN-TPA and DCN-SAC.
A517: 702 | B517: (10^-9.0) * Meter^(1.0) | C517: λema | D517: https://doi.org/10.1002/adom.202300368 | F517: 616 | G517: C1(=CC=CC=C1)N(C1=CC=C(C=C1)C1=CC2=C(C3=NC4=CC(=C(C=C4N=C3C3=C2C=CC=C3)C#N)C#N)C=C1)C1=CC=CC=C1 | I517: 616 🙃🙃🙃🙃 DCN - Ph - DPA 🙃🙃🙃🙃 Nema ) [ nm ]; Table 1. Summary of the photophysical properties of DCN-Ph-DPA and DCN-SP-DPA.
A518: 703 | B518: (10^-9.0) * Meter^(1.0) | C518: λema | D518: https://doi.org/10.1002/adom.202300368 | F518: 622 | G518: C1(=CC=CC=C1)N(C1=CC=2C3(C4=CC(=CC=C4C2C=C1)C1=CC2=C(C4=NC5=CC(=C(C=C5N=C4C4=C2C=CC=C4)C#N)C#N)C=C1)C1=CC=CC=C1C=1C=CC=CC13)C1=CC=CC=C1 | I518: 622 🙃🙃🙃🙃 DCN - SP - DPA 🙃🙃🙃🙃 Nema ) [ nm ]; Table 1. Summary of the photophysical properties of DCN-Ph-DPA and DCN-SP-DPA.
A519: 704 | B519: (10^-9.0) * Meter^(1.0) | C519: λem | D519: https://doi.org/10.1002/chem.202401250 | F519: 512 | G519: C1(=CC=CC=C1)C1=NC(=NC(=N1)C1=CC=CC=C1)C1=CC=C(C=C1)N1C=2C=CC(=CC2C(C2=CC(=CC=C12)C1=C(C=CC=C1)F)(C)C)C1=C(C=CC=C1)F | I519: 512 🙃🙃🙃🙃 2,7 - F - Ph - DMAC - TRZ 🙃🙃🙃🙃 Nem [ nm ]; ![](images/174f76d2eeac0b647d07111684f0bde2d1d8c111bcec618cdd15999d7652e4b9.jpg)
A520: 705 | B520: (10^-9.0) * Meter^(1.0) | C520: λem | D520: https://doi.org/10.1002/chem.202401250 | F520: 504 | G520: C1(=CC=CC=C1)C1=NC(=NC(=N1)C1=CC=CC=C1)C1=CC=C(C=C1)N1C=2C=CC(=CC2C(C2=CC(=CC=C12)C1=C(C=CC=C1)C(F)(F)F)(C)C)C1=C(C=CC=C1)C(F)(F)F | I520: 504 🙃🙃🙃🙃 2,7 - CF3 - Ph - DMAC - TRZ 🙃🙃🙃🙃 Nem [ nm ]; ![](images/174f76d2eeac0b647d07111684f0bde2d1d8c111bcec618cdd15999d7652e4b9.jpg)
A521: 706 | B521: (10^-9.0) * Meter^(1.0) | C521: λpLa | D521: https://doi.org/10.1002/adfm.202105805 | F521: 446 | G521: C1=CC=CC=2OC=3C=C(C=C4OC=5C=CC=CC5B(C34)C12)N1C=2C=CC=CC2C2=C3C(=C4N(C=5C=CC=CC5C4=C21)C2=CC=CC=C2)C2=C(O3)C=CC=C2 | I521: 446 🙃🙃🙃🙃 DBA - BFICz 🙃🙃🙃🙃 NpLa ) [ nm ]; Table 1. Photophysical properties of DBA-BFICz and DBA-BTICz.
A522: 707 | B522: (10^-9.0) * Meter^(1.0) | C522: λpLa | D522: https://doi.org/10.1002/adfm.202105805 | F522: 445 | G522: C1=CC=CC=2OC=3C=C(C=C4OC=5C=CC=CC5B(C34)C12)N1C=2C=CC=CC2C2=C3C(=C4N(C=5C=CC=CC5C4=C21)C2=CC=CC=C2)C2=C(S3)C=CC=C2 | I522: 445 🙃🙃🙃🙃 DBA - BTICz 🙃🙃🙃🙃 NpLa ) [ nm ]; Table 1. Photophysical properties of DBA-BFICz and DBA-BTICz.
A523: 708 | B523: (10^-9.0) * Meter^(1.0) | C523: λemb | D523: https://doi.org/10.1002/adom.201700145 | E523: Cyclohexane | F523: 625 | G523: CC1(C2=CC=CC=C2N(C=2C=CC=CC12)C1=CC=C(C=C1)C1=C2C=CC=CC2=C(C2=NSN=C21)C2=CC=C(C=C2)N2C=1C=CC=CC1C(C1=CC=CC=C21)(C)C)C | I523: 625 🙃🙃🙃🙃 Cyclohexane 🙃🙃🙃🙃 Nemb ) [ nm ]; Table 1. Photophysical properties of NZ2AC in different solvents.
A524: 709 | B524: (10^-9.0) * Meter^(1.0) | C524: λemb | D524: https://doi.org/10.1002/adom.201700145 | E524: Toluene | F524: 631 | G524: CC1(C2=CC=CC=C2N(C=2C=CC=CC12)C1=CC=C(C=C1)C1=C2C=CC=CC2=C(C2=NSN=C21)C2=CC=C(C=C2)N2C=1C=CC=CC1C(C1=CC=CC=C21)(C)C)C | I524: 631 🙃🙃🙃🙃 Toluene 🙃🙃🙃🙃 Nemb ) [ nm ]; Table 1. Photophysical properties of NZ2AC in different solvents.
A525: 710 | B525: (10^-9.0) * Meter^(1.0) | C525: λemb | D525: https://doi.org/10.1002/adom.201700145 | E525: Chloroform | F525: 663 | G525: CC1(C2=CC=CC=C2N(C=2C=CC=CC12)C1=CC=C(C=C1)C1=C2C=CC=CC2=C(C2=NSN=C21)C2=CC=C(C=C2)N2C=1C=CC=CC1C(C1=CC=CC=C21)(C)C)C | I525: 663 🙃🙃🙃🙃 Chloroform 🙃🙃🙃🙃 Nemb ) [ nm ]; Table 1. Photophysical properties of NZ2AC in different solvents.
A526: 711 | B526: (10^-9.0) * Meter^(1.0) | C526: λemb | D526: https://doi.org/10.1002/adom.201700145 | E526: Tetrahydrofuran | F526: 668 | G526: CC1(C2=CC=CC=C2N(C=2C=CC=CC12)C1=CC=C(C=C1)C1=C2C=CC=CC2=C(C2=NSN=C21)C2=CC=C(C=C2)N2C=1C=CC=CC1C(C1=CC=CC=C21)(C)C)C | I526: 668 🙃🙃🙃🙃 Tetrahydrofuran 🙃🙃🙃🙃 Nemb ) [ nm ]; Table 1. Photophysical properties of NZ2AC in different solvents.
A527: 712 | B527: (10^-9.0) * Meter^(1.0) | C527: λemb | D527: https://doi.org/10.1002/adom.201700145 | E527: Dichloromethane | F527: 663 | G527: CC1(C2=CC=CC=C2N(C=2C=CC=CC12)C1=CC=C(C=C1)C1=C2C=CC=CC2=C(C2=NSN=C21)C2=CC=C(C=C2)N2C=1C=CC=CC1C(C1=CC=CC=C21)(C)C)C | I527: 663 🙃🙃🙃🙃 Dichloromethane 🙃🙃🙃🙃 Nemb ) [ nm ]; Table 1. Photophysical properties of NZ2AC in different solvents.
A528: 713 | B528: (10^-9.0) * Meter^(1.0) | C528: λem | D528: https://doi.org/10.1002/ange.201600113 | E528: cyclohexane | F528: 457 | G528: CC(C1=CC2=C(N(C3=CC4=CC=C5C(N=C(C(C=CC(N6C7=C(C8=C6C=CC(C(C)(C)C)=C8)C=C(C(C)(C)C)C=C7)=C9)=C9C=C%10)C%10=N5)=C4C=C3)C%11=C2C=C(C(C)(C)C)C=C%11)C=C1)(C)C | H528: 1 | I528: 457 / 509 🙃🙃🙃🙃 t - BuCZ - DBPHZ 🙃🙃🙃🙃 Nem [ nm ] ( in c - hexl @ / in CBP filmb ); Table 1: Summary of properties of DBPHZs.
A529: 714 | B529: (10^-9.0) * Meter^(1.0) | C529: λMax. | D529: https://doi.org/10.1002/advs.201800436 | E529: toluene | F529: 612 | G529: C1=CC=CC=2OC3=CC=CC=C3N(C12)C=1C=CC2=C(C3=C(C4=NC5=C6C(=C7C(=C5N=C24)C=CC=N7)N=CC=C6)C=CC(=C3)N3C6=CC=CC=C6OC=6C=CC=CC36)C1 | H529: 1 | I529: 612 🙃🙃🙃🙃 DPXZ - BPPZ 🙃🙃🙃🙃 NMax . [ nm ] 🙃🙃🙃🙃 NMax . [ nm ]; Table 1. Summary of performances of red TADF OLEDs (ELmax≥670 nm) ).
A530: 715 | B530: (10^-9.0) * Meter^(1.0) | C530: PL | D530: https://doi.org/10.1002/adfm.202411957 | F530: 501 | G530: C1=CC=CC2=C1N1C3=C2C=CC=C3OC=3C=CC=CC13 | I530: 501 🙃🙃🙃🙃 1 🙃🙃🙃🙃 1 🙃🙃🙃🙃 PL [ nm ]; Table 1. Emission characteristics of emitters 1 and 2 doped (xwt-%) in the PPF films.
A531: 716 | B531: (10^-9.0) * Meter^(1.0) | C531: PL | D531: https://doi.org/10.1002/adfm.202411957 | F531: 506 | G531: C1=CC=CC2=C1N1C3=C2C=CC=C3OC=3C=CC=CC13 | I531: 506 🙃🙃🙃🙃 1 🙃🙃🙃🙃 20 🙃🙃🙃🙃 PL [ nm ]; Table 1. Emission characteristics of emitters 1 and 2 doped (xwt-%) in the PPF films.
A532: 717 | B532: (10^-9.0) * Meter^(1.0) | C532: PL | D532: https://doi.org/10.1002/adfm.202411957 | F532: 500 | G532: C1=CC=CC2=C1N1C3=C2C=CC=C3OC=3C=CC=CC13 | I532: 500 🙃🙃🙃🙃 2 🙃🙃🙃🙃 1 🙃🙃🙃🙃 PL [ nm ]; Table 1. Emission characteristics of emitters 1 and 2 doped (xwt-%) in the PPF films.
A533: 718 | B533: (10^-9.0) * Meter^(1.0) | C533: PL | D533: https://doi.org/10.1002/adfm.202411957 | F533: 508 | G533: C1=CC=CC2=C1N1C3=C2C=CC=C3OC=3C=CC=CC13 | I533: 508 🙃🙃🙃🙃 2 🙃🙃🙃🙃 20 🙃🙃🙃🙃 PL [ nm ]; Table 1. Emission characteristics of emitters 1 and 2 doped (xwt-%) in the PPF films.
A534: 719 | B534: (10^-9.0) * Meter^(1.0) | C534: λem | D534: https://doi.org/10.1002/adom.202002019 | E534: THF | F534: 510 | G534: O=C(C1=CC=C(N2C(C=CC=C3)=C3C4(C(C=CC=C5)=C5C6=C4C=CC=C6)C7=C2C=CC=C7)C=C1)C(C=C8C9=C%10C=CC=C9)=CC=C8N%10C(C=C%11)=CC=C%11N%12C%13=CC=CC=C%13C%14=C%12C=CC=C%14 | H534: 1 | I534: 510 🙃🙃🙃🙃 Nem [ nm ] 🙃🙃🙃🙃 solutiona ); Table 1. The photophysical data of DCB-BP-SFAC.
A535: 720 | B535: (10^-9.0) * Meter^(1.0) | C535: λema | D535: https://doi.org/10.1002/adfm.202304398 | E535: toluene | F535: 648 | G535: N#CC(C=C1N=C2C3=C4C=C(C5=CC=C(N(C6=CC=C(C(C=CC=C7)=C7C89C(C=CC=C%10)=C%10C%11=C9C=CC=C%11)C8=C6)C%12=CC=CC=C%12)C=C5)C=C3)=C(C#N)C=C1N=C2C%13=C4C=CC=C%13 | H535: 1 | I535: 648 🙃🙃🙃🙃 DCN - SPTPA 🙃🙃🙃🙃 Nema ) [ nm ]; Table 1. Summary of the photophysical properties of DCN-PhTPA and DCN-SPTPA.
A536: 721 | B536: (10^-9.0) * Meter^(1.0) | C536: λem | D536: https://doi.org/10.1002/adom.201600304 | E536: toluene | F536: 543 | G536: C1=CC=CC=2OC3=CC=CC=C3N(C12)C=1C=NC2=C3N=CC(=CC3=CC=C2C1)N1C2=CC=CC=C2OC=2C=CC=CC12 | H536: 1 | I536: 543 🙃🙃🙃🙃 m - PXZP 🙃🙃🙃🙃 Nem [ nm ] a ); Table 2. Physical properties of ±bx-PXZP.
A537: 722 | B537: (10^-9.0) * Meter^(1.0) | C537: λem | D537: https://doi.org/10.1002/adom.201600304 | E537: toluene | F537: 535 | G537: C1=CC=CC=2OC3=CC=CC=C3N(C12)C1=CC=NC2=C3N=CC=C(C3=CC=C12)N1C2=CC=CC=C2OC=2C=CC=CC12 | H537: 1 | I537: 535 🙃🙃🙃🙃 p - PXZP 🙃🙃🙃🙃 Nem [ nm ] a ); Table 2. Physical properties of ±bx-PXZP.
A538: 723 | B538: (10^-9.0) * Meter^(1.0) | C538: λem | D538: https://doi.org/10.1002/adom.201600304 | E538: toluene | F538: 554 | G538: C1=CC=CC=2OC3=CC=CC=C3N(C12)C1=NC2=C3N=C(C=CC3=CC=C2C=C1)N1C2=CC=CC=C2OC=2C=CC=CC12 | H538: 1 | I538: 535 🙃🙃🙃🙃 o - PXZP 🙃🙃🙃🙃 Nem [ nm ] a ); Table 2. Physical properties of ±bx-PXZP.
A539: 724 | B539: (10^-9.0) * Meter^(1.0) | C539: λem | D539: https://doi.org/10.1002/ange.201906575 | E539: toluene | F539: 607 | G539: C1=CC=NC2=C3C(=C4N=C5C6=C(C7=C(C5=NC4=C21)C=CC=C7)C=C(C=C6)N6C7=CC=CC=C7OC=7C=CC=CC67)C=CC=N3 | H539: 1 | I539: 607 🙃🙃🙃🙃 BPPZ - PXZ 🙃🙃🙃🙃 Nem [ nm ] ( b ]; Tabelle 1: Summary of physical properties of BPPZ-PXZ and mDPBPZ-PXZ.
A540: 725 | B540: (10^-9.0) * Meter^(1.0) | C540: λem | D540: https://doi.org/10.1002/ange.201906575 | F540: 638 | G540: N1=CC(=CC=C1)C=1C=C2N=C3C4=C(C5=C(C3=NC2=CC1C=1C=NC=CC1)C=CC(=C5)N5C1=CC=CC=C1OC=1C=CC=CC51)C=CC=C4 | I540: 638 🙃🙃🙃🙃 mDPBPZ - PXZ 🙃🙃🙃🙃 Nem [ nm ] ( b ]; Tabelle 1: Summary of physical properties of BPPZ-PXZ and mDPBPZ-PXZ.
...

Sheet 4_ml_cols_only
A1: _id | B1: doi | C1: solvent | D1: standard_value | E1: smiles | F1: corrected
A2: 0 | B2: https://doi.org/10.1016/j.cej.2022.135775 | C2: toluene | D2: 638 | E2: N1=CC=C(C=C1)C=1C=C2N=C3C(=NC2=CC1C1=CC=NC=C1)C=1C=CC(=C2C=CC=C3C12)N1C2=CC=CC=C2OC=2C=CC=CC12 | F2: 1
A3: 1 | B3: https://doi.org/10.1016/j.cej.2022.135775 | C3: toluene | D3: 639 | E3: N1=CC=C(C=C1)C=1C=C2N=C3C4=C(C5=C(C3=NC2=CC1C1=CC=NC=C1)C=CC(=C5)N5C1=CC=CC=C1OC=1C=CC=CC51)C=CC=C4 | F3: 1
A4: 2 | B4: https://doi.org/10.1016/j.dyepig.2023.111250 | C4: toluene | D4: 465 | E4: C1(=CC=CC=C1)C1=NC(=NC(=N1)C1=CC=CC=C1)C1=C(C=CC=C1)N1C2=CC=CC=C2C=2C=CC=CC12 | F4: 1
A5: 17 | B5: https://doi.org/10.1016/j.cej.2020.127591 | C5: toluene | D5: 415 | E5: C1=CC=CC=2C=3C=CC4=C(C3N(C12)C1=NC=C(N=C1)N1C=2C=CC=CC2C=2C=CC3=C(C12)OC1=C3C=CC=C1)OC1=C4C=CC=C1 | F5: 1
A6: 18 | B6: https://doi.org/10.1016/j.cej.2020.127591 | C6: toluene | D6: 444 | E6: C1=C2C=3C4=C(C=CC3N(C2=CC=C1)C1=NC=C(N=C1)N1C2=CC=CC=C2C=2C3=C(C=CC12)C1=C(O3)C=CC=C1)C1=C(O4)C=CC=C1 | F6: 1
A7: 19 | B7: https://doi.org/10.1016/j.cej.2020.127591 | C7: toluene | D7: 444 | E7: C1=CC=CC2=C1C=1C(=CC=C3C4=CC=CC=C4N(C13)C1=NC=C(N=C1)N1C3=CC=CC=C3C3=CC=C4C(=C13)C1=C(O4)C=CC=C1)O2 | F7: 1
A8: 20 | B8: https://doi.org/10.1016/j.cej.2020.127591 | C8: toluene | D8: 456 | E8: C1=CC=CC=2C=3C=CC4=C(C3N(C12)C1=NC=C(N=C1)N1C=2C=CC=CC2C=2C=CC3=C(C12)SC1=C3C=CC=C1)SC1=C4C=CC=C1 | F8: 1
A9: 21 | B9: https://doi.org/10.1016/j.cej.2020.127591 | C9: toluene | D9: 444 | E9: C1=C2C=3C4=C(C=CC3N(C2=CC=C1)C1=NC=C(N=C1)N1C2=CC=CC=C2C=2C3=C(C=CC12)C1=C(S3)C=CC=C1)C1=C(S4)C=CC=C1 | F9: 1
A10: 22 | B10: https://doi.org/10.1016/j.cej.2020.127591 | C10: toluene | D10: 454 | E10: C1=CC(=CC=2C3=CC=CC=C3N(C12)C1=NC=C(N=C1)N1C2=CC=CC=C2C=2C=C(C=CC12)N1C2=CC=CC=C2C=2C=CC=CC12)N1C2=CC=CC=C2C=2C=CC=CC12 | F10: 1
A11: 66 | B11: https://doi.org/10.1016/j.dyepig.2018.09.072 | C11: toluene | D11: 459 | E11: C1=CC=CC=2C3=CC=CC=C3N(C12)C1=C(C=CC=C1)C1=NC(=NC(=N1)C1=CC=CC=C1)C1=CC=C(C=C1)C1=NC(=NC(=N1)C1=C(C=CC=C1)N1C2=CC=CC=C2C=2C=CC=CC12)C1=CC=CC=C1 | F11: 1
A12: 67 | B12: https://doi.org/10.1016/j.dyepig.2018.09.072 | C12: toluene | D12: 477 | E12: C(C)(C)(C)C=1C=CC=2N(C3=CC=C(C=C3C2C1)C(C)(C)C)C1=C(C=CC=C1)C1=NC(=NC(=N1)C1=CC=CC=C1)C1=CC=C(C=C1)C1=NC(=NC(=N1)C1=C(C=CC=C1)N1C2=CC=C(C=C2C=2C=C(C=CC12)C(C)(C)C)C(C)(C)C)C1=CC=CC=C1 | F12: 1
A13: 91 | B13: https://doi.org/10.1016/j.cej.2023.146326 | C13: THF | D13: 500 | E13: C1=CC=CC=2C3=CC=CC=C3N(C12)C=1C=C(C=C(C1)N1C2=CC=CC=C2C=2C=CC=CC12)S(=O)(=O)C=1C=C(C=C(C1)N1C=2C=CC=CC2C(C2=CC=CC=C12)(C)C)N1C=2C=CC=CC2C(C2=CC=CC=C12)(C)C | F13: 1
... A646: 646 | B646: https://doi.org/10.1039/C4TC02547D | C646: dichloromethane | D646: 401 | E646: C(CC)C1(C2=CC=CC=C2C=2C=CC(=CC12)C#CC1=CC=C2C=3C=CC(=CC3C(C2=C1)(CCC)CCC)C#N)CCC | F646: 0
A647: 700 | B647: https://doi.org/10.1002/adfm.202420489 | D647: 616 | E647: C1(=CC=CC=C1)N(C1=CC=C(C=C1)C1=CC2=C(C3=NC4=CC(=C(C=C4N=C3C3=C2C=CC=C3)C#N)C#N)C=C1)C1=CC=CC=C1 | F647: 0
A648: 701 | B648: https://doi.org/10.1002/adfm.202420489 | D648: 606 | E648: C1(=CC=CC=C1)N1C=2C=CC(=CC2C2(C3=CC=CC=C3C=3C=CC=CC23)C2=CC=CC=C12)C1=CC2=C(C3=NC4=CC(=C(C=C4N=C3C3=C2C=CC=C3)C#N)C#N)C=C1 | F648: 0
A649: 702 | B649: https://doi.org/10.1002/adom.202300368 | D649: 616 | E649: C1(=CC=CC=C1)N(C1=CC=C(C=C1)C1=CC2=C(C3=NC4=CC(=C(C=C4N=C3C3=C2C=CC=C3)C#N)C#N)C=C1)C1=CC=CC=C1 | F649: 0
A650: 703 | B650: https://doi.org/10.1002/adom.202300368 | D650: 622 | E650: C1(=CC=CC=C1)N(C1=CC=2C3(C4=CC(=CC=C4C2C=C1)C1=CC2=C(C4=NC5=CC(=C(C=C5N=C4C4=C2C=CC=C4)C#N)C#N)C=C1)C1=CC=CC=C1C=1C=CC=CC13)C1=CC=CC=C1 | F650: 0
A651: 704 | B651: https://doi.org/10.1002/chem.202401250 | D651: 512 | E651: C1(=CC=CC=C1)C1=NC(=NC(=N1)C1=CC=CC=C1)C1=CC=C(C=C1)N1C=2C=CC(=CC2C(C2=CC(=CC=C12)C1=C(C=CC=C1)F)(C)C)C1=C(C=CC=C1)F | F651: 0
A652: 705 | B652: https://doi.org/10.1002/chem.202401250 | D652: 504 | E652: C1(=CC=CC=C1)C1=NC(=NC(=N1)C1=CC=CC=C1)C1=CC=C(C=C1)N1C=2C=CC(=CC2C(C2=CC(=CC=C12)C1=C(C=CC=C1)C(F)(F)F)(C)C)C1=C(C=CC=C1)C(F)(F)F | F652: 0
A653: 706 | B653: https://doi.org/10.1002/adfm.202105805 | D653: 446 | E653: C1=CC=CC=2OC=3C=C(C=C4OC=5C=CC=CC5B(C34)C12)N1C=2C=CC=CC2C2=C3C(=C4N(C=5C=CC=CC5C4=C21)C2=CC=CC=C2)C2=C(O3)C=CC=C2 | F653: 0
A654: 707 | B654: https://doi.org/10.1002/adfm.202105805 | D654: 445 | E654: C1=CC=CC=2OC=3C=C(C=C4OC=5C=CC=CC5B(C34)C12)N1C=2C=CC=CC2C2=C3C(=C4N(C=5C=CC=CC5C4=C21)C2=CC=CC=C2)C2=C(S3)C=CC=C2 | F654: 0
